Workbook
Name SegmentaciónDeDatos_Clase: #N/A
Name SegmentaciónDeDatos_Marca1: #N/A

Sheet Datos HTML
F1: {=VLOOKUP(_xlfn.SINGLE(C:C),'[1]Price List'!$C:$H,{4,5,6},0)} -> #N/A | K1: =SUBTOTAL(9,K3:K1048576) -> 139929 | O1: =SUBTOTAL(9,O3:O1165) -> 40555 | P1: =SUBTOTAL(9,P3:P1165) -> 30146 | Q1: =SUBTOTAL(9,Q3:Q1165) -> 26943 | R1: =SUBTOTAL(9,R3:R1165) -> 26624 | S1: =SUBTOTAL(9,S3:S1165) -> 25404 | T1: =SUBTOTAL(9,T3:T1165) -> 25104 | U1: =SUBTOTAL(9,U3:U1165) -> 25155 | V1: =SUBTOTAL(9,V3:V1165) -> 25596 | ... Z1: =SUBTOTAL(9,Z3:Z1165) -> 49167 | AA1: =SUBTOTAL(9,AA3:AA1048576) -> 11828974 | AB1: =SUBTOTAL(9,AB3:AB1048576) -> 9226992.9 | AC1: =SUBTOTAL(9,AC3:AC1048576) -> 8294344.6 | AD1: =SUBTOTAL(9,AD3:AD1048576) -> 7422632 | AE1: =SUBTOTAL(9,AE3:AE1048576) -> 7355363.7 | AF1: =SUBTOTAL(9,AF3:AF1048576) -> 7105609.6 | AG1: =SUBTOTAL(9,AG3:AG1048576) -> 6920620.6 | AH1: =SUBTOTAL(9,AH3:AH1048576) -> 7596590.9 | ... AL1: =SUBTOTAL(9,AL3:AL1048576) -> 15197205
A2: Marca | B2: SKU Retail | C2: ITEM | D2: UPC | E2: Descripción | F2: Categoría | G2: Sub Categoría | H2: Clase | I2: Retail | J2: Type | K2: Roll Out | L2: Cost | M2: Status ACA | N2: Status Retail | O2: FCST Jan | P2: FCST Feb | Q2: FCST Mar | R2: FCST Apr | S2: FCST May | T2: FCST Jun | U2: FCST Jul | V2: FCST Aug | W2: FCST Sep | X2: FCST Oct | Y2: FCST Nov | Z2: FCST Dec | AA2: Jan | AB2: Feb | AC2: Mar | AD2: Apr | AE2: May | AF2: Jun | AG2: Jul | AH2: Aug | AI2: Sep | AJ2: Oct | AK2: Nov | AL2: Dec
A3: Speck | B3: 228994 | C3: 150986-D143 | D3: 840168546589 | E3: Speck Presidio2 Grip iPhone 17 Pro Max Black | F3: Cases iPhone | G3: iPhone 17 | H3: iPhone 17 Pro Max | I3: Coppel | J3: Firme | K3: 1500 | L3: 447.83 | M3: Descontinuado | N3: Discontinued | O3: {=IFERROR(VLOOKUP(_xlfn.SINGLE(B:B),'[1]Pivot SI'!$D:$AN,{6,7,8,9,10,11,12},0),0)} -> 0 | P3: 0 | Q3: 0 | R3: 260 | S3: 0 | T3: 0 | U3: 0 | V3: 0 | W3: 0 | X3: 0 | Y3: 0 | Z3: 0 | AA3: =O3*$L:$L -> 0 | AB3: =P3*$L:$L -> 0 | AC3: =Q3*$L:$L -> 0 | AD3: =R3*$L:$L -> 116435.8 | AE3: =S3*$L:$L -> 0 | AF3: =T3*$L:$L -> 0 | AG3: =U3*$L:$L -> 0 | AH3: =V3*$L:$L -> 0 | ... AL3: =Z3*$L:$L -> 0
A4: Speck | B4: 228977 | C4: 150983-3199 | D4: 840168546541 | E4: Speck Presidio Perfect-Clear Grip + Cl Clear/Clear/Silver Iphone 17 Pro Max | F4: Cases iPhone | G4: iPhone 17 | H4: iPhone 17 Pro Max | I4: Coppel | J4: Firme | K4: 1500 | L4: 447.83 | M4: Descontinuado | N4: Discontinued | O4: {=IFERROR(VLOOKUP(_xlfn.SINGLE(B:B),'[1]Pivot SI'!$D:$AN,{6,7,8,9,10,11,12},0),0)} -> 0 | P4: 0 | Q4: 0 | R4: 260 | S4: 0 | T4: 0 | U4: 0 | V4: 0 | W4: 0 | X4: 0 | Y4: 0 | Z4: 0 | AA4: =O4*$L:$L -> 0 | AB4: =P4*$L:$L -> 0 | AC4: =Q4*$L:$L -> 0 | AD4: =R4*$L:$L -> 116435.8 | AE4: =S4*$L:$L -> 0 | AF4: =T4*$L:$L -> 0 | AG4: =U4*$L:$L -> 0 | AH4: =V4*$L:$L -> 0 | ... AL4: =Z4*$L:$L -> 0
A5: Speck | B5: 228969 | C5: 150697-5085 | D5: 840168540655 | E5: Speck iPhone 16 Gemshell Grip +Ms Clear/Clear | F5: Cases iPhone | G5: iPhone | H5: iPhone 16 | I5: Coppel | J5: Firme | K5: 450 | L5: 223.69 | M5: Descontinuado | O5: {=IFERROR(VLOOKUP(_xlfn.SINGLE(B:B),'[1]Pivot SI'!$D:$AN,{6,7,8,9,10,11,12},0),0)} -> 0 | P5: 0 | Q5: 0 | R5: 650 | S5: 0 | T5: 0 | U5: 0 | V5: 0 | W5: 0 | X5: 0 | Y5: 0 | Z5: 0 | AA5: =O5*$L:$L -> 0 | AB5: =P5*$L:$L -> 0 | AC5: =Q5*$L:$L -> 0 | AD5: =R5*$L:$L -> 145398.5 | AE5: =S5*$L:$L -> 0 | AF5: =T5*$L:$L -> 0 | AG5: =U5*$L:$L -> 0 | AH5: =V5*$L:$L -> 0 | ... AL5: =Z5*$L:$L -> 0
A6: Speck | B6: 229044 | C6: 150443-3199 | D6: 840168532865 | E6: Speck Presidio® Perfect-Clear Grip Magsafe® Clicklock™ Clear/Clear/Chrome iPhone 15 | F6: Cases iPhone | G6: iPhone | H6: iPhone 16e / 15 / 14 / 13 | I6: Coppel | J6: Firme | K6: 450 | L6: 223.69 | M6: Descontinuado | O6: {=IFERROR(VLOOKUP(_xlfn.SINGLE(B:B),'[1]Pivot SI'!$D:$AN,{6,7,8,9,10,11,12},0),0)} -> 0 | P6: 0 | Q6: 0 | R6: 300 | S6: 0 | T6: 0 | U6: 0 | V6: 0 | W6: 0 | X6: 0 | Y6: 0 | Z6: 0 | AA6: =O6*$L:$L -> 0 | AB6: =P6*$L:$L -> 0 | AC6: =Q6*$L:$L -> 0 | AD6: =R6*$L:$L -> 67107 | AE6: =S6*$L:$L -> 0 | AF6: =T6*$L:$L -> 0 | AG6: =U6*$L:$L -> 0 | AH6: =V6*$L:$L -> 0 | ... AL6: =Z6*$L:$L -> 0
A7: Nomad | B7: 856504014339 | C7: NM014339858 | D7: 856504014339 | E7: Nomad Modern Leather Case - iPhone 17 Pro | Black | Nomad Leather | F7: Cases iPhone | G7: iPhone 17 | H7: iPhone 17 Pro | I7: iShop | J7: Firme | K7: 320 | L7: 521.08 | M7: Descontinuado | N7: Active | O7: 59 | P7: 82 | Q7: 24 | R7: 10 | S7: 71 | T7: 14 | U7: 50 | V7: 50 | W7: 0 | X7: 0 | Y7: 0 | Z7: 0 | AA7: =O7*$L:$L -> 30743.72 | AB7: =P7*$L:$L -> 42728.56 | AC7: =Q7*$L:$L -> 12505.92 | AD7: =R7*$L:$L -> 5210.8 | AE7: =S7*$L:$L -> 36996.68 | AF7: =T7*$L:$L -> 7295.12 | AG7: =U7*$L:$L -> 26054 | AH7: =V7*$L:$L -> 26054 | ... AL7: =Z7*$L:$L -> 0 | AN7: =C7&I7 -> NM014339858iShop | AO7: {=IFERROR(VLOOKUP(_xlfn.SINGLE(AN:AN),'[1]Pivot SI'!$R:$Y,{2,3,4,5,6,7,8},0),0)} -> 59 | AP7: 82 | AQ7: 24 | AR7: 10 | AS7: 71 | AT7: 14 | AU7: 50
A8: Nomad | B8: 856504014322 | C8: NM014322858 | D8: 856504014322 | E8: Nomad Modern Leather Case - iPhone 17 Pro | Brown | Nomad Leather | F8: Cases iPhone | G8: iPhone 17 | H8: iPhone 17 Pro | I8: iShop | J8: Firme | K8: 320 | L8: 521.08 | M8: Descontinuado | N8: Active | O8: 40 | P8: 3 | Q8: 8 | R8: 17 | S8: 56 | T8: 22 | U8: 27 | V8: 18 | W8: 0 | X8: 0 | Y8: 0 | Z8: 0 | AA8: =O8*$L:$L -> 20843.2 | AB8: =P8*$L:$L -> 1563.24 | AC8: =Q8*$L:$L -> 4168.64 | AD8: =R8*$L:$L -> 8858.36 | AE8: =S8*$L:$L -> 29180.48 | AF8: =T8*$L:$L -> 11463.76 | AG8: =U8*$L:$L -> 14069.16 | AH8: =V8*$L:$L -> 9379.44 | ... AL8: =Z8*$L:$L -> 0 | AN8: =C8&I8 -> NM014322858iShop | AO8: {=IFERROR(VLOOKUP(_xlfn.SINGLE(AN:AN),'[1]Pivot SI'!$R:$Y,{2,3,4,5,6,7,8},0),0)} -> 40 | AP8: 3 | AQ8: 8 | AR8: 17 | AS8: 56 | AT8: 22 | AU8: 27
A9: Nomad | B9: 856504014285 | C9: NM014285858 | D9: 856504014285 | E9: Nomad Modern Leather Case - iPhone 17 Pro Max | Black | Nomad Leather | F9: Cases iPhone | G9: iPhone 17 | H9: iPhone 17 Pro Max | I9: iShop | J9: Firme | K9: 320 | L9: 521.08 | M9: Descontinuado | N9: Active | O9: 152 | P9: 1 | Q9: 218 | R9: 59 | S9: 117 | T9: 49 | U9: 96 | V9: 80 | W9: 0 | X9: 0 | Y9: 0 | Z9: 0 | AA9: =O9*$L:$L -> 79204.16 | AB9: =P9*$L:$L -> 521.08 | AC9: =Q9*$L:$L -> 113595.44 | AD9: =R9*$L:$L -> 30743.72 | AE9: =S9*$L:$L -> 60966.36 | AF9: =T9*$L:$L -> 25532.92 | AG9: =U9*$L:$L -> 50023.68 | AH9: =V9*$L:$L -> 41686.4 | ... AL9: =Z9*$L:$L -> 0 | AN9: =C9&I9 -> NM014285858iShop | AO9: {=IFERROR(VLOOKUP(_xlfn.SINGLE(AN:AN),'[1]Pivot SI'!$R:$Y,{2,3,4,5,6,7,8},0),0)} -> 152 | AP9: 1 | AQ9: 218 | AR9: 59 | AS9: 117 | AT9: 49 | AU9: 96
A10: Nomad | B10: 856504014278 | C10: NM014278858 | D10: 856504014278 | E10: Nomad Modern Leather Case - iPhone 17 Pro Max | Brown | Nomad Leather | F10: Cases iPhone | G10: iPhone 17 | H10: iPhone 17 Pro Max | I10: iShop | J10: Firme | K10: 320 | L10: 521.08 | M10: Descontinuado | N10: Active | O10: 101 | P10: 155 | Q10: 185 | R10: 56 | S10: 100 | T10: 66 | U10: 74 | V10: 80 | W10: 0 | X10: 0 | Y10: 0 | Z10: 0 | AA10: =O10*$L:$L -> 52629.08 | AB10: =P10*$L:$L -> 80767.4 | AC10: =Q10*$L:$L -> 96399.8 | AD10: =R10*$L:$L -> 29180.48 | AE10: =S10*$L:$L -> 52108 | AF10: =T10*$L:$L -> 34391.28 | AG10: =U10*$L:$L -> 38559.92 | AH10: =V10*$L:$L -> 41686.4 | ... AL10: =Z10*$L:$L -> 0 | AN10: =C10&I10 -> NM014278858iShop | AO10: {=IFERROR(VLOOKUP(_xlfn.SINGLE(AN:AN),'[1]Pivot SI'!$R:$Y,{2,3,4,5,6,7,8},0),0)} -> 101 | AP10: 155 | AQ10: 185 | AR10: 56 | AS10: 100 | AT10: 66 | AU10: 74
A11: Speck | B11: 840168546428 | C11: 150976-D143 | D11: 840168546428 | E11: Speck Presidio2 Grip + MS iPhone 17 Pro Black | F11: Cases iPhone | G11: iPhone 17 | H11: iPhone 17 Pro | I11: iShop | J11: Firme | K11: 320 | L11: 387.54 | M11: Descontinuado | N11: Active | O11: 4 | P11: 0 | Q11: 2 | R11: 12 | S11: 0 | T11: 0 | U11: 55 | V11: 4 | W11: 130 | X11: 0 | Y11: 0 | Z11: 0 | AA11: =O11*$L:$L -> 1550.16 | AB11: =P11*$L:$L -> 0 | AC11: =Q11*$L:$L -> 775.08 | AD11: =R11*$L:$L -> 4650.48 | AE11: =S11*$L:$L -> 0 | AF11: =T11*$L:$L -> 0 | AG11: =U11*$L:$L -> 21314.7 | AH11: =V11*$L:$L -> 1550.16 | ... AL11: =Z11*$L:$L -> 0 | AN11: =C11&I11 -> 150976-D143iShop | AO11: {=IFERROR(VLOOKUP(_xlfn.SINGLE(AN:AN),'[1]Pivot SI'!$R:$Y,{2,3,4,5,6,7,8},0),0)} -> 0
A12: Speck | B12: 840168546411 | C12: 150975-D143 | D12: 840168546411 | E12: Speck Presidio2 + MS iPhone 17 Pro Black/Slate Grey/White | F12: Cases iPhone | G12: iPhone 17 | H12: iPhone 17 Pro | I12: iShop | J12: Firme | K12: 320 | L12: 387.54 | M12: Descontinuado | N12: Active | O12: 8 | P12: 0 | Q12: 0 | R12: 0 | S12: 26 | T12: 0 | U12: 36 | V12: 0 | W12: 0 | X12: 0 | Y12: 0 | Z12: 0 | AA12: =O12*$L:$L -> 3100.32 | AB12: =P12*$L:$L -> 0 | AC12: =Q12*$L:$L -> 0 | AD12: =R12*$L:$L -> 0 | AE12: =S12*$L:$L -> 10076.04 | AF12: =T12*$L:$L -> 0 | AG12: =U12*$L:$L -> 13951.44 | AH12: =V12*$L:$L -> 0 | ... AL12: =Z12*$L:$L -> 0 | AN12: =C12&I12 -> 150975-D143iShop | AO12: {=IFERROR(VLOOKUP(_xlfn.SINGLE(AN:AN),'[1]Pivot SI'!$R:$Y,{2,3,4,5,6,7,8},0),0)} -> 0
A13: Speck | B13: 840168547302 | C13: 151020-3261 | D13: 840168547302 | E13: Speck Presidio2 + MS iPhone 17 Pro Deep Sea/Silver Metallic/Spell Blue | F13: Cases iPhone | G13: iPhone 17 | H13: iPhone 17 Pro | I13: iShop | J13: Firme | K13: 320 | L13: 387.54 | M13: Descontinuado | N13: Active | O13: 0 | P13: 28 | Q13: 0 | R13: 8 | S13: 19 | T13: 0 | U13: 37 | V13: 17 | W13: 20 | X13: 0 | Y13: 0 | Z13: 0 | AA13: =O13*$L:$L -> 0 | AB13: =P13*$L:$L -> 10851.12 | AC13: =Q13*$L:$L -> 0 | AD13: =R13*$L:$L -> 3100.32 | AE13: =S13*$L:$L -> 7363.26 | AF13: =T13*$L:$L -> 0 | AG13: =U13*$L:$L -> 14338.98 | AH13: =V13*$L:$L -> 6588.18 | ... AL13: =Z13*$L:$L -> 0 | AN13: =C13&I13 -> 151020-3261iShop | AO13: {=IFERROR(VLOOKUP(_xlfn.SINGLE(AN:AN),'[1]Pivot SI'!$R:$Y,{2,3,4,5,6,7,8},0),0)} -> 0
A14: Speck | B14: 840168546381 | C14: 150972-3240 | D14: 840168546381 | E14: Speck Presidio Perfect-Clear iPhone 17 Pro Clear | F14: Cases iPhone | G14: iPhone 17 | H14: iPhone 17 Pro | I14: iShop | J14: Firme | K14: 320 | L14: 387.54 | M14: Descontinuado | N14: Active | O14: 27 | P14: 62 | Q14: 28 | R14: 0 | S14: 36 | T14: 52 | U14: 58 | V14: 25 | W14: 0 | X14: 0 | Y14: 0 | Z14: 0 | AA14: =O14*$L:$L -> 10463.58 | AB14: =P14*$L:$L -> 24027.48 | AC14: =Q14*$L:$L -> 10851.12 | AD14: =R14*$L:$L -> 0 | AE14: =S14*$L:$L -> 13951.44 | AF14: =T14*$L:$L -> 20152.08 | AG14: =U14*$L:$L -> 22477.32 | AH14: =V14*$L:$L -> 9688.5 | ... AL14: =Z14*$L:$L -> 0 | AN14: =C14&I14 -> 150972-3240iShop | AO14: {=IFERROR(VLOOKUP(_xlfn.SINGLE(AN:AN),'[1]Pivot SI'!$R:$Y,{2,3,4,5,6,7,8},0),0)} -> 0
A15: Speck | B15: 840168546558 | C15: 150984-D143 | D15: 840168546558 | E15: Speck Presidio2 + MS iPhone 17 Pro Max Black/Slate Grey/White | F15: Cases iPhone | G15: iPhone 17 | H15: iPhone 17 Pro Max | I15: iShop | J15: Firme | K15: 320 | L15: 387.54 | M15: Descontinuado | N15: Active | O15: 0 | P15: 133 | Q15: 44 | R15: 29 | S15: 64 | T15: 0 | U15: 16 | V15: 0 | W15: 0 | X15: 0 | Y15: 0 | Z15: 0 | AA15: =O15*$L:$L -> 0 | AB15: =P15*$L:$L -> 51542.82 | AC15: =Q15*$L:$L -> 17051.76 | AD15: =R15*$L:$L -> 11238.66 | AE15: =S15*$L:$L -> 24802.56 | AF15: =T15*$L:$L -> 0 | AG15: =U15*$L:$L -> 6200.64 | AH15: =V15*$L:$L -> 0 | ... AL15: =Z15*$L:$L -> 0 | AN15: =C15&I15 -> 150984-D143iShop | AO15: {=IFERROR(VLOOKUP(_xlfn.SINGLE(AN:AN),'[1]Pivot SI'!$R:$Y,{2,3,4,5,6,7,8},0),0)} -> 0
A16: Speck | B16: 840168547401 | C16: 151025-3261 | D16: 840168547401 | E16: Speck Presidio2 + MS iPhone 17 Pro Max Deep Sea/Silver Metallic/Spell Blue | F16: Cases iPhone | G16: iPhone 17 | H16: iPhone 17 Pro Max | I16: iShop | J16: Firme | K16: 320 | L16: 387.54 | M16: Descontinuado | N16: Active | O16: 0 | P16: 198 | Q16: 24 | R16: 2 | S16: 40 | T16: 0 | U16: 1 | V16: 0 | W16: 0 | X16: 0 | Y16: 0 | Z16: 0 | AA16: =O16*$L:$L -> 0 | AB16: =P16*$L:$L -> 76732.92 | AC16: =Q16*$L:$L -> 9300.96 | AD16: =R16*$L:$L -> 775.08 | AE16: =S16*$L:$L -> 15501.6 | AF16: =T16*$L:$L -> 0 | AG16: =U16*$L:$L -> 387.54 | AH16: =V16*$L:$L -> 0 | ... AL16: =Z16*$L:$L -> 0 | AN16: =C16&I16 -> 151025-3261iShop | AO16: {=IFERROR(VLOOKUP(_xlfn.SINGLE(AN:AN),'[1]Pivot SI'!$R:$Y,{2,3,4,5,6,7,8},0),0)} -> 0
A17: Speck | B17: 840168546527 | C17: 150981-3240 | D17: 840168546527 | E17: Speck Presidio Perfect-Clear iPhone 17 Pro Max Clear | F17: Cases iPhone | G17: iPhone 17 | H17: iPhone 17 Pro Max | I17: iShop | J17: Firme | K17: 320 | L17: 387.54 | M17: Descontinuado | N17: Active | O17: 44 | P17: 319 | Q17: 272 | R17: 105 | S17: 121 | T17: 89 | U17: 2 | V17: 70 | W17: 0 | X17: 0 | Y17: 0 | Z17: 0 | AA17: =O17*$L:$L -> 17051.76 | AB17: =P17*$L:$L -> 123625.26 | AC17: =Q17*$L:$L -> 105410.88 | AD17: =R17*$L:$L -> 40691.7 | AE17: =S17*$L:$L -> 46892.34 | AF17: =T17*$L:$L -> 34491.06 | AG17: =U17*$L:$L -> 775.08 | AH17: =V17*$L:$L -> 27127.8 | ... AL17: =Z17*$L:$L -> 0 | AN17: =C17&I17 -> 150981-3240iShop | AO17: {=IFERROR(VLOOKUP(_xlfn.SINGLE(AN:AN),'[1]Pivot SI'!$R:$Y,{2,3,4,5,6,7,8},0),0)} -> 0
A18: Speck | B18: 840168546589 | C18: 150986-D143 | D18: 840168546589 | E18: Speck Presidio2 Grip iPhone 17 Pro Max Black | F18: Cases iPhone | G18: iPhone 17 | H18: iPhone 17 Pro Max | I18: iShop | J18: Firme | K18: 320 | L18: 387.54 | M18: Descontinuado | N18: Active | O18: 0 | P18: 78 | Q18: 46 | R18: 18 | S18: 47 | T18: 2 | U18: 0 | V18: 0 | W18: 0 | X18: 0 | Y18: 0 | Z18: 0 | AA18: =O18*$L:$L -> 0 | AB18: =P18*$L:$L -> 30228.12 | AC18: =Q18*$L:$L -> 17826.84 | AD18: =R18*$L:$L -> 6975.72 | AE18: =S18*$L:$L -> 18214.38 | AF18: =T18*$L:$L -> 775.08 | AG18: =U18*$L:$L -> 0 | AH18: =V18*$L:$L -> 0 | ... AL18: =Z18*$L:$L -> 0 | AN18: =C18&I18 -> 150986-D143iShop | AO18: {=IFERROR(VLOOKUP(_xlfn.SINGLE(AN:AN),'[1]Pivot SI'!$R:$Y,{2,3,4,5,6,7,8},0),0)} -> 0
A19: Tech21 | B19: 840459607258 | C19: T21-11323 | D19: 840459607258 | E19: Tech21 EvoClear iPhone 17 Pro Clear | F19: Cases iPhone | G19: iPhone 17 | H19: iPhone 17 Pro | I19: iShop | J19: Firme | K19: 320 | L19: 387.5 | M19: Descontinuado | N19: Active | O19: 47 | P19: 49 | Q19: 16 | R19: 46 | S19: 99 | T19: 24 | U19: 48 | V19: 20 | W19: 0 | X19: 0 | Y19: 0 | Z19: 0 | AA19: =O19*$L:$L -> 18212.5 | AB19: =P19*$L:$L -> 18987.5 | AC19: =Q19*$L:$L -> 6200 | AD19: =R19*$L:$L -> 17825 | AE19: =S19*$L:$L -> 38362.5 | AF19: =T19*$L:$L -> 9300 | AG19: =U19*$L:$L -> 18600 | AH19: =V19*$L:$L -> 7750 | ... AL19: =Z19*$L:$L -> 0 | AN19: =C19&I19 -> T21-11323iShop | AO19: {=IFERROR(VLOOKUP(_xlfn.SINGLE(AN:AN),'[1]Pivot SI'!$R:$Y,{2,3,4,5,6,7,8},0),0)} -> 0
A20: Tech21 | B20: 840459607371 | C20: T21-11334 | D20: 840459607371 | E20: Tech21 EvoClear iPhone 17 Pro Max Clear | F20: Cases iPhone | G20: iPhone 17 | H20: iPhone 17 Pro Max | I20: iShop | J20: Firme | K20: 320 | L20: 387.5 | M20: Descontinuado | N20: Active | O20: 0 | P20: 236 | Q20: 215 | R20: 73 | S20: 92 | T20: 46 | U20: 25 | V20: 17 | W20: 0 | X20: 0 | Y20: 0 | Z20: 0 | AA20: =O20*$L:$L -> 0 | AB20: =P20*$L:$L -> 91450 | AC20: =Q20*$L:$L -> 83312.5 | AD20: =R20*$L:$L -> 28287.5 | AE20: =S20*$L:$L -> 35650 | AF20: =T20*$L:$L -> 17825 | AG20: =U20*$L:$L -> 9687.5 | AH20: =V20*$L:$L -> 6587.5 | ... AL20: =Z20*$L:$L -> 0 | AN20: =C20&I20 -> T21-11334iShop | AO20: {=IFERROR(VLOOKUP(_xlfn.SINGLE(AN:AN),'[1]Pivot SI'!$R:$Y,{2,3,4,5,6,7,8},0),0)} -> 0
A21: Speck | C21: 151119-5085 | E21: Speck Presidio Perfect Clear Fold + MagSafe Clear iPhone 18 FOLD | F21: Cases iPhone | G21: iPhone 18 | H21: iPhone 18 Fold | I21: iShop | J21: Firme | K21: 200 | L21: 503.92241 | M21: New | N21: New | O21: 0 | V21: 0 | W21: 250 | X21: 30 | Y21: 30 | Z21: 30 | AA21: =O21*$L:$L -> 0 | AB21: =P21*$L:$L -> 0 | AC21: =Q21*$L:$L -> 0 | AD21: =R21*$L:$L -> 0 | AE21: =S21*$L:$L -> 0 | AF21: =T21*$L:$L -> 0 | AG21: =U21*$L:$L -> 0 | AH21: =V21*$L:$L -> 0 | ... AL21: =Z21*$L:$L -> 15117.672 | AN21: =C21&I21 -> 151119-5085iShop | AO21: {=IFERROR(VLOOKUP(_xlfn.SINGLE(AN:AN),'[1]Pivot SI'!$R:$Y,{2,3,4,5,6,7,8},0),0)} -> 0
A22: Speck | C22: 151098-3240 | E22: Speck Presidio Perfect Clear + C-MagSafe/CC Clear iPhone 18 Pro | F22: Cases iPhone | G22: iPhone 18 | H22: iPhone 18 Pro | I22: iShop | J22: Firme | K22: 320 | L22: 387.54 | M22: New | N22: New | O22: 0 | V22: 0 | W22: 280 | X22: 180 | Y22: 120 | Z22: 180 | AA22: =O22*$L:$L -> 0 | AB22: =P22*$L:$L -> 0 | AC22: =Q22*$L:$L -> 0 | AD22: =R22*$L:$L -> 0 | AE22: =S22*$L:$L -> 0 | AF22: =T22*$L:$L -> 0 | AG22: =U22*$L:$L -> 0 | AH22: =V22*$L:$L -> 0 | ... AL22: =Z22*$L:$L -> 69757.2 | AN22: =C22&I22 -> 151098-3240iShop | AO22: {=IFERROR(VLOOKUP(_xlfn.SINGLE(AN:AN),'[1]Pivot SI'!$R:$Y,{2,3,4,5,6,7,8},0),0)} -> 0
A23: Speck | C23: 151096-D143 | E23: Speck Presidio2 Grip + MagSafe/CC Black iPhone 18 Pro | F23: Cases iPhone | G23: iPhone 18 | H23: iPhone 18 Pro | I23: iShop | J23: Firme | K23: 320 | L23: 387.5431 | M23: New | N23: New | O23: 0 | V23: 0 | W23: 120 | X23: 30 | Y23: 45 | Z23: 30 | AA23: =O23*$L:$L -> 0 | AB23: =P23*$L:$L -> 0 | AC23: =Q23*$L:$L -> 0 | AD23: =R23*$L:$L -> 0 | AE23: =S23*$L:$L -> 0 | AF23: =T23*$L:$L -> 0 | AG23: =U23*$L:$L -> 0 | AH23: =V23*$L:$L -> 0 | ... AL23: =Z23*$L:$L -> 11626.293 | AN23: =C23&I23 -> 151096-D143iShop | AO23: {=IFERROR(VLOOKUP(_xlfn.SINGLE(AN:AN),'[1]Pivot SI'!$R:$Y,{2,3,4,5,6,7,8},0),0)} -> 0
A24: Speck | C24: 151096-3261 | E24: Speck Presidio2 Grip + MagSafe/CC Deep Sea iPhone 18 Pro | F24: Cases iPhone | G24: iPhone 18 | H24: iPhone 18 Pro | I24: iShop | J24: Firme | K24: 320 | L24: 387.5431 | M24: New | N24: New | O24: 0 | V24: 0 | W24: 200 | X24: 35 | Y24: 35 | Z24: 35 | AA24: =O24*$L:$L -> 0 | AB24: =P24*$L:$L -> 0 | AC24: =Q24*$L:$L -> 0 | AD24: =R24*$L:$L -> 0 | AE24: =S24*$L:$L -> 0 | AF24: =T24*$L:$L -> 0 | AG24: =U24*$L:$L -> 0 | AH24: =V24*$L:$L -> 0 | ... AL24: =Z24*$L:$L -> 13564.009 | AN24: =C24&I24 -> 151096-3261iShop | AO24: {=IFERROR(VLOOKUP(_xlfn.SINGLE(AN:AN),'[1]Pivot SI'!$R:$Y,{2,3,4,5,6,7,8},0),0)} -> 0
A25: Speck | C25: 151104-9984 | E25: Speck Presidio Lux Grip + C-MagSafe/CC Obsidian iPhone 18 Pro | F25: Cases iPhone | G25: iPhone 18 | H25: iPhone 18 Pro | I25: iShop | J25: Firme | K25: 320 | L25: 387.5431 | M25: New | N25: New | O25: 0 | V25: 0 | W25: 220 | X25: 20 | Y25: 20 | Z25: 20 | AA25: =O25*$L:$L -> 0 | AB25: =P25*$L:$L -> 0 | AC25: =Q25*$L:$L -> 0 | AD25: =R25*$L:$L -> 0 | AE25: =S25*$L:$L -> 0 | AF25: =T25*$L:$L -> 0 | AG25: =U25*$L:$L -> 0 | AH25: =V25*$L:$L -> 0 | ... AL25: =Z25*$L:$L -> 7750.8621 | AN25: =C25&I25 -> 151104-9984iShop | AO25: {=IFERROR(VLOOKUP(_xlfn.SINGLE(AN:AN),'[1]Pivot SI'!$R:$Y,{2,3,4,5,6,7,8},0),0)} -> 0
A26: Speck | C26: 151110-3240 | E26: Speck Presidio Perfect Clear + C-MagSafe/CC Clear iPhone 18 Pro Max | F26: Cases iPhone | G26: iPhone 18 | H26: iPhone 18 Pro Max | I26: iShop | J26: Firme | K26: 320 | L26: 387.54 | M26: New | N26: New | O26: 0 | V26: 0 | W26: 280 | X26: 220 | Y26: 280 | Z26: 200 | AA26: =O26*$L:$L -> 0 | AB26: =P26*$L:$L -> 0 | AC26: =Q26*$L:$L -> 0 | AD26: =R26*$L:$L -> 0 | AE26: =S26*$L:$L -> 0 | AF26: =T26*$L:$L -> 0 | AG26: =U26*$L:$L -> 0 | AH26: =V26*$L:$L -> 0 | ... AL26: =Z26*$L:$L -> 77508 | AN26: =C26&I26 -> 151110-3240iShop | AO26: {=IFERROR(VLOOKUP(_xlfn.SINGLE(AN:AN),'[1]Pivot SI'!$R:$Y,{2,3,4,5,6,7,8},0),0)} -> 0
A27: Speck | C27: 151108-D143 | E27: Speck Presidio2 Grip + MagSafe/CC Black iPhone 18 Pro Max | F27: Cases iPhone | G27: iPhone 18 | H27: iPhone 18 Pro Max | I27: iShop | J27: Firme | K27: 320 | L27: 387.5431 | M27: New | N27: New | O27: 0 | V27: 0 | W27: 280 | X27: 100 | Y27: 65 | Z27: 65 | AA27: =O27*$L:$L -> 0 | AB27: =P27*$L:$L -> 0 | AC27: =Q27*$L:$L -> 0 | AD27: =R27*$L:$L -> 0 | AE27: =S27*$L:$L -> 0 | AF27: =T27*$L:$L -> 0 | AG27: =U27*$L:$L -> 0 | AH27: =V27*$L:$L -> 0 | ... AL27: =Z27*$L:$L -> 25190.302 | AN27: =C27&I27 -> 151108-D143iShop | AO27: {=IFERROR(VLOOKUP(_xlfn.SINGLE(AN:AN),'[1]Pivot SI'!$R:$Y,{2,3,4,5,6,7,8},0),0)} -> 0
A28: Speck | C28: 151108-3261 | E28: Speck Presidio2 Grip + MagSafe/CC Deep Sea iPhone 18 Pro Max | F28: Cases iPhone | G28: iPhone 18 | H28: iPhone 18 Pro Max | I28: iShop | J28: Firme | K28: 320 | L28: 387.5431 | M28: New | N28: New | O28: 0 | V28: 0 | W28: 220 | X28: 120 | Y28: 150 | Z28: 80 | AA28: =O28*$L:$L -> 0 | AB28: =P28*$L:$L -> 0 | AC28: =Q28*$L:$L -> 0 | AD28: =R28*$L:$L -> 0 | AE28: =S28*$L:$L -> 0 | AF28: =T28*$L:$L -> 0 | AG28: =U28*$L:$L -> 0 | AH28: =V28*$L:$L -> 0 | ... AL28: =Z28*$L:$L -> 31003.448 | AN28: =C28&I28 -> 151108-3261iShop | AO28: {=IFERROR(VLOOKUP(_xlfn.SINGLE(AN:AN),'[1]Pivot SI'!$R:$Y,{2,3,4,5,6,7,8},0),0)} -> 0
A29: Speck | C29: 151116-9984 | E29: Speck Presidio Lux Grip + C-MagSafe/CC Obsidian iPhone 18 Pro Max | F29: Cases iPhone | G29: iPhone 18 | H29: iPhone 18 Pro Max | I29: iShop | J29: Firme | K29: 320 | L29: 387.5431 | M29: New | N29: New | O29: 0 | V29: 0 | W29: 250 | X29: 30 | Y29: 30 | Z29: 30 | AA29: =O29*$L:$L -> 0 | AB29: =P29*$L:$L -> 0 | AC29: =Q29*$L:$L -> 0 | AD29: =R29*$L:$L -> 0 | AE29: =S29*$L:$L -> 0 | AF29: =T29*$L:$L -> 0 | AG29: =U29*$L:$L -> 0 | AH29: =V29*$L:$L -> 0 | ... AL29: =Z29*$L:$L -> 11626.293 | AN29: =C29&I29 -> 151116-9984iShop | AO29: {=IFERROR(VLOOKUP(_xlfn.SINGLE(AN:AN),'[1]Pivot SI'!$R:$Y,{2,3,4,5,6,7,8},0),0)} -> 0
A30: Tech21 | C30: T21-11730 | E30: Tech21 EvoClear w/MagSafe Clear iPhone 18 FOLD | F30: Cases iPhone | G30: iPhone 18 | H30: iPhone 18 Fold | I30: iShop | J30: Firme | K30: 200 | L30: 559.91379 | M30: New | N30: New | O30: 0 | V30: 0 | W30: 250 | X30: 50 | Y30: 50 | Z30: 50 | AA30: =O30*$L:$L -> 0 | AB30: =P30*$L:$L -> 0 | AC30: =Q30*$L:$L -> 0 | AD30: =R30*$L:$L -> 0 | AE30: =S30*$L:$L -> 0 | AF30: =T30*$L:$L -> 0 | AG30: =U30*$L:$L -> 0 | AH30: =V30*$L:$L -> 0 | ... AL30: =Z30*$L:$L -> 27995.69 | AN30: =C30&I30 -> T21-11730iShop | AO30: {=IFERROR(VLOOKUP(_xlfn.SINGLE(AN:AN),'[1]Pivot SI'!$R:$Y,{2,3,4,5,6,7,8},0),0)} -> 0
A31: Tech21 | C31: T21-11655 | E31: Tech21 EvoClear w/C-MagSafe/CC Clear iPhone 18 Pro | F31: Cases iPhone | G31: iPhone 18 | H31: iPhone 18 Pro | I31: iShop | J31: Firme | K31: 320 | L31: 387.5 | M31: New | N31: New | O31: 0 | V31: 0 | W31: 300 | X31: 100 | Y31: 120 | Z31: 80 | AA31: =O31*$L:$L -> 0 | AB31: =P31*$L:$L -> 0 | AC31: =Q31*$L:$L -> 0 | AD31: =R31*$L:$L -> 0 | AE31: =S31*$L:$L -> 0 | AF31: =T31*$L:$L -> 0 | AG31: =U31*$L:$L -> 0 | AH31: =V31*$L:$L -> 0 | ... AL31: =Z31*$L:$L -> 31000 | AN31: =C31&I31 -> T21-11655iShop | AO31: {=IFERROR(VLOOKUP(_xlfn.SINGLE(AN:AN),'[1]Pivot SI'!$R:$Y,{2,3,4,5,6,7,8},0),0)} -> 0
A32: Tech21 | C32: T21-11740 | E32: Tech21 Apple AP-1041 EvoClear w/C-MagSafe/CC - Mandala Pattern | F32: Cases iPhone | G32: iPhone 18 | H32: iPhone 18 Pro | I32: iShop | J32: Firme | K32: 320 | L32: 430.60345 | M32: New | N32: New | O32: 0 | V32: 0 | W32: 360 | X32: 45 | Y32: 80 | Z32: 80 | AA32: =O32*$L:$L -> 0 | AB32: =P32*$L:$L -> 0 | AC32: =Q32*$L:$L -> 0 | AD32: =R32*$L:$L -> 0 | AE32: =S32*$L:$L -> 0 | AF32: =T32*$L:$L -> 0 | AG32: =U32*$L:$L -> 0 | AH32: =V32*$L:$L -> 0 | ... AL32: =Z32*$L:$L -> 34448.276 | AN32: =C32&I32 -> T21-11740iShop | AO32: {=IFERROR(VLOOKUP(_xlfn.SINGLE(AN:AN),'[1]Pivot SI'!$R:$Y,{2,3,4,5,6,7,8},0),0)} -> 0
... A46: Nomad | C46: NM009162858 | E46: Nomad Modern Leather Case - iPhone 18 Pro Max | Brown | Nomad Leather | F46: Cases iPhone | G46: iPhone 18 | H46: iPhone 18 Pro Max | I46: iShop | J46: Firme | K46: 320 | L46: 473.7069 | M46: New | N46: New | O46: 0 | V46: 0 | W46: 280 | X46: 180 | Y46: 210 | Z46: 150 | AA46: =O46*$L:$L -> 0 | AB46: =P46*$L:$L -> 0 | AC46: =Q46*$L:$L -> 0 | AD46: =R46*$L:$L -> 0 | AE46: =S46*$L:$L -> 0 | AF46: =T46*$L:$L -> 0 | AG46: =U46*$L:$L -> 0 | AH46: =V46*$L:$L -> 0 | ... AL46: =Z46*$L:$L -> 71056.034 | AN46: =C46&I46 -> NM009162858iShop | AO46: {=IFERROR(VLOOKUP(_xlfn.SINGLE(AN:AN),'[1]Pivot SI'!$R:$Y,{2,3,4,5,6,7,8},0),0)} -> 0
A47: Nomad | B47: 856504011291 | C47: NM011291858 | D47: 856504011291 | E47: Nomad Modern Leather Case - Airpods Pro 3 | Black | Horween | F47: Cases Airpods | G47: Airpods | H47: Airpods Pro 3 | I47: iShop | J47: Firme | K47: 220 | L47: 344.4 | M47: Activo | N47: Active | O47: 221 | P47: 137 | Q47: 177 | R47: 62 | S47: 168 | T47: 76 | U47: 56 | V47: 80 | W47: 80 | X47: 30 | Y47: 30 | Z47: 30 | AA47: =O47*$L:$L -> 76112.4 | AB47: =P47*$L:$L -> 47182.8 | AC47: =Q47*$L:$L -> 60958.8 | AD47: =R47*$L:$L -> 21352.8 | AE47: =S47*$L:$L -> 57859.2 | AF47: =T47*$L:$L -> 26174.4 | AG47: =U47*$L:$L -> 19286.4 | AH47: =V47*$L:$L -> 27552 | ... AL47: =Z47*$L:$L -> 10332 | AN47: =C47&I47 -> NM011291858iShop | AO47: {=IFERROR(VLOOKUP(_xlfn.SINGLE(AN:AN),'[1]Pivot SI'!$R:$Y,{2,3,4,5,6,7,8},0),0)} -> 221 | AP47: 137 | AQ47: 177 | AR47: 62 | AS47: 168 | AT47: 76 | AU47: 56
A48: Nomad | B48: 856504011284 | C48: NM011284858 | D48: 856504011284 | E48: Nomad Modern Leather Case - Airpods Pro 3 | Rustic Brown | Horween | F48: Cases Airpods | G48: Airpods | H48: Airpods Pro 3 | I48: iShop | J48: Firme | K48: 220 | L48: 344.4 | M48: Activo | N48: Active | O48: 214 | P48: 97 | Q48: 121 | R48: 51 | S48: 107 | T48: 77 | U48: 29 | V48: 80 | W48: 80 | X48: 84 | Y48: 30 | Z48: 30 | AA48: =O48*$L:$L -> 73701.6 | AB48: =P48*$L:$L -> 33406.8 | AC48: =Q48*$L:$L -> 41672.4 | AD48: =R48*$L:$L -> 17564.4 | AE48: =S48*$L:$L -> 36850.8 | AF48: =T48*$L:$L -> 26518.8 | AG48: =U48*$L:$L -> 9987.6 | AH48: =V48*$L:$L -> 27552 | ... AL48: =Z48*$L:$L -> 10332 | AN48: =C48&I48 -> NM011284858iShop | AO48: {=IFERROR(VLOOKUP(_xlfn.SINGLE(AN:AN),'[1]Pivot SI'!$R:$Y,{2,3,4,5,6,7,8},0),0)} -> 214 | AP48: 97 | AQ48: 121 | AR48: 51 | AS48: 107 | AT48: 77 | AU48: 29
A49: Nomad | B49: 856500018522 | C49: NM1Am10000 | D49: 856500018522 | E49: Nomad Sport Strap - 45/44mm/42mm | M/L | Black | FKM | V2 | F49: Straps | G49: Apple Watch | H49: 49/45/44/42 mm | I49: iShop | J49: Firme | K49: 200 | L49: 473.71 | M49: Activo | N49: Active | O49: 100 | P49: 126 | Q49: 192 | R49: 118 | S49: 260 | T49: 91 | U49: 90 | V49: 144 | W49: 120 | X49: 291 | Y49: 250 | Z49: 200 | AA49: =O49*$L:$L -> 47371 | AB49: =P49*$L:$L -> 59687.46 | AC49: =Q49*$L:$L -> 90952.32 | AD49: =R49*$L:$L -> 55897.78 | AE49: =S49*$L:$L -> 123164.6 | AF49: =T49*$L:$L -> 43107.61 | AG49: =U49*$L:$L -> 42633.9 | AH49: =V49*$L:$L -> 68214.24 | ... AL49: =Z49*$L:$L -> 94742 | AN49: =C49&I49 -> NM1Am10000iShop | AO49: {=IFERROR(VLOOKUP(_xlfn.SINGLE(AN:AN),'[1]Pivot SI'!$R:$Y,{2,3,4,5,6,7,8},0),0)} -> 100 | AP49: 126 | AQ49: 192 | AR49: 118 | AS49: 260 | AT49: 91 | AU49: 90
A50: Nomad | B50: 855848007366 | C50: NM00736685 | D50: 855848007366 | E50: Nomad Sport Band - 45mm | Ultra Orange | F50: Straps | G50: Apple Watch | H50: 49/45/44/42 mm | I50: iShop | J50: Firme | K50: 200 | L50: 473.71 | M50: Activo | N50: Active | O50: 1 | P50: 162 | Q50: 239 | R50: 106 | S50: 174 | T50: 66 | U50: 72 | V50: 150 | W50: 120 | X50: 80 | Y50: 362 | Z50: 110 | AA50: =O50*$L:$L -> 473.71 | AB50: =P50*$L:$L -> 76741.02 | AC50: =Q50*$L:$L -> 113216.69 | AD50: =R50*$L:$L -> 50213.26 | AE50: =S50*$L:$L -> 82425.54 | AF50: =T50*$L:$L -> 31264.86 | AG50: =U50*$L:$L -> 34107.12 | AH50: =V50*$L:$L -> 71056.5 | ... AL50: =Z50*$L:$L -> 52108.1 | AN50: =C50&I50 -> NM00736685iShop | AO50: {=IFERROR(VLOOKUP(_xlfn.SINGLE(AN:AN),'[1]Pivot SI'!$R:$Y,{2,3,4,5,6,7,8},0),0)} -> 1 | AP50: 162 | AQ50: 239 | AR50: 106 | AS50: 174 | AT50: 66 | AU50: 72
A51: Nomad | B51: 856504014919 | C51: NM014919858 | D51: 856504014919 | E51: Nomad Sport Band - 49/45/44mm/42mm | M/L | Naval | F51: Straps | G51: Apple Watch | H51: 49/45/44/42 mm | I51: iShop | J51: Firme | K51: 200 | L51: 473.71 | M51: Activo2 | N51: Active | O51: 1 | P51: 0 | Q51: 152 | R51: 84 | S51: 24 | T51: 67 | U51: 91 | V51: 80 | W51: 80 | X51: 90 | Y51: 110 | Z51: 80 | AA51: =O51*$L:$L -> 473.71 | AB51: =P51*$L:$L -> 0 | AC51: =Q51*$L:$L -> 72003.92 | AD51: =R51*$L:$L -> 39791.64 | AE51: =S51*$L:$L -> 11369.04 | AF51: =T51*$L:$L -> 31738.57 | AG51: =U51*$L:$L -> 43107.61 | AH51: =V51*$L:$L -> 37896.8 | ... AL51: =Z51*$L:$L -> 37896.8 | AN51: =C51&I51 -> NM014919858iShop | AO51: {=IFERROR(VLOOKUP(_xlfn.SINGLE(AN:AN),'[1]Pivot SI'!$R:$Y,{2,3,4,5,6,7,8},0),0)} -> 1 | AP51: 0 | AQ51: 152 | AR51: 84 | AS51: 24 | AT51: 67 | AU51: 91
A52: Nomad | B52: 856504014803 | C52: NM014803858 | D52: 856504014803 | E52: Nomad Rocky Point Band - 46mm/49mm | Storm | Black Hardware | F52: Straps | G52: Apple Watch | H52: 49/45/44/42 mm | I52: iShop | J52: Firme | K52: 180 | L52: 775.43 | M52: Activo2 | N52: Active | O52: 0 | P52: 171 | Q52: 154 | R52: 92 | S52: 171 | T52: 6 | U52: 78 | V52: 37 | AA52: =O52*$L:$L -> 0 | AB52: =P52*$L:$L -> 132598.53 | AC52: =Q52*$L:$L -> 119416.22 | AD52: =R52*$L:$L -> 71339.56 | AE52: =S52*$L:$L -> 132598.53 | AF52: =T52*$L:$L -> 4652.58 | AG52: =U52*$L:$L -> 60483.54 | AH52: =V52*$L:$L -> 28690.91 | ... AL52: =Z52*$L:$L -> 0 | AN52: =C52&I52 -> NM014803858iShop | AO52: {=IFERROR(VLOOKUP(_xlfn.SINGLE(AN:AN),'[1]Pivot SI'!$R:$Y,{2,3,4,5,6,7,8},0),0)} -> 0 | AP52: 171 | AQ52: 154 | AR52: 92 | AS52: 171 | AT52: 6 | AU52: 78
A53: Nomad | B53: 856504014827 | C53: NM014827858 | D53: 856504014827 | E53: Nomad Rocky Point Band - 46mm/49mm | Atlantic | Black Hardware | F53: Straps | G53: Apple Watch | H53: 49/45/44/42 mm | I53: iShop | J53: Firme | K53: 180 | L53: 775.43 | M53: Activo | N53: Active | O53: 0 | P53: 154 | Q53: 77 | R53: 0 | S53: 82 | T53: 35 | U53: 49 | V53: 18 | W53: 0 | X53: 95 | Y53: 40 | Z53: 65 | AA53: =O53*$L:$L -> 0 | AB53: =P53*$L:$L -> 119416.22 | AC53: =Q53*$L:$L -> 59708.11 | AD53: =R53*$L:$L -> 0 | AE53: =S53*$L:$L -> 63585.26 | AF53: =T53*$L:$L -> 27140.05 | AG53: =U53*$L:$L -> 37996.07 | AH53: =V53*$L:$L -> 13957.74 | ... AL53: =Z53*$L:$L -> 50402.95 | AN53: =C53&I53 -> NM014827858iShop | AO53: {=IFERROR(VLOOKUP(_xlfn.SINGLE(AN:AN),'[1]Pivot SI'!$R:$Y,{2,3,4,5,6,7,8},0),0)} -> 0 | AP53: 154 | AQ53: 77 | AR53: 0 | AS53: 82 | AT53: 35 | AU53: 49
...

Sheet Master iP17 iP18
A1: Marca | B1: ITEM iP18 | C1: Descripción iP18 | D1: Clase | E1: iTEM iP17 | F1: Descripción iP17 | G1: ITEM iP | H1: Descripcion
A2: Nomad | B2: NM009162858 | C2: Nomad Modern Leather Case - iPhone 18 Pro Max | Brown | Nomad Leather | D2: iPhone 18 Pro Max | E2: NM014278858 | F2: Nomad Modern Leather Case - iPhone 17 Pro Max | Brown | Nomad Leather | G2: =CONCATENATE(E2,"-",B2) -> NM014278858-NM009162858 | H2: =C2 -> Nomad Modern Leather Case - iPhone 18 Pro Max | Brown | Nomad Leather
A3: Nomad | B3: NM009179858 | C3: Nomad Modern Leather Case - iPhone 18 Pro Max | Black | Nomad Leather | D3: iPhone 18 Pro Max | E3: NM014285858 | F3: Nomad Modern Leather Case - iPhone 17 Pro Max | Black | Nomad Leather | G3: =CONCATENATE(E3,"-",B3) -> NM014285858-NM009179858 | H3: =C3 -> Nomad Modern Leather Case - iPhone 18 Pro Max | Black | Nomad Leather
A4: Nomad | B4: NM009247858 | C4: Nomad Modern Leather Case - iPhone 18 Pro | Brown | Nomad Leather | D4: iPhone 18 Pro | E4: NM014322858 | F4: Nomad Modern Leather Case - iPhone 17 Pro | Brown | Nomad Leather | G4: =CONCATENATE(E4,"-",B4) -> NM014322858-NM009247858 | H4: =C4 -> Nomad Modern Leather Case - iPhone 18 Pro | Brown | Nomad Leather
A5: Nomad | B5: NM009254858 | C5: Nomad Modern Leather Case - iPhone 18 Pro | Black | Nomad Leather | D5: iPhone 18 Pro | E5: NM014339858 | F5: Nomad Modern Leather Case - iPhone 17 Pro | Black | Nomad Leather | G5: =CONCATENATE(E5,"-",B5) -> NM014339858-NM009254858 | H5: =C5 -> Nomad Modern Leather Case - iPhone 18 Pro | Black | Nomad Leather
A6: Speck | B6: 151096-3261 | C6: Speck Presidio2 Grip + MagSafe/CC Deep Sea iPhone 18 Pro | D6: iPhone 18 Pro | E6: 151020-3261 | F6: Speck Presidio2 + MS iPhone 17 Pro Deep Sea/Silver Metallic/Spell Blue | G6: =CONCATENATE(E6,"-",B6) -> 151020-3261-151096-3261 | H6: =C6 -> Speck Presidio2 Grip + MagSafe/CC Deep Sea iPhone 18 Pro
A7: Speck | B7: 151096-D143 | C7: Speck Presidio2 Grip + MagSafe/CC Black iPhone 18 Pro | D7: iPhone 18 Pro | E7: 150976-D143 | F7: Speck Presidio2 Grip + MS iPhone 17 Pro Black | G7: =CONCATENATE(E7,"-",B7) -> 150976-D143-151096-D143 | H7: =C7 -> Speck Presidio2 Grip + MagSafe/CC Black iPhone 18 Pro
A8: Speck | B8: 151098-3240 | C8: Speck Presidio Perfect Clear + C-MagSafe/CC Clear iPhone 18 Pro | D8: iPhone 18 Pro | E8: 150972-3240 | F8: Speck Presidio Perfect-Clear iPhone 17 Pro Clear | G8: =CONCATENATE(E8,"-",B8) -> 150972-3240-151098-3240 | H8: =C8 -> Speck Presidio Perfect Clear + C-MagSafe/CC Clear iPhone 18 Pro
A9: Speck | B9: 151106-9221 | C9: Speck Presidio Lux + C-MagSafe/CC Gold Glitter iPhone 18 Pro | D9: iPhone 18 Pro | E9: 150978-9221 | F9: Speck Presidio Lux iPhone 17 Pro Glitter/Gold | G9: =CONCATENATE(E9,"-",B9) -> 150978-9221-151106-9221 | H9: =C9 -> Speck Presidio Lux + C-MagSafe/CC Gold Glitter iPhone 18 Pro
A10: Speck | B10: 151108-3261 | C10: Speck Presidio2 Grip + MagSafe/CC Deep Sea iPhone 18 Pro Max | D10: iPhone 18 Pro Max | E10: 151025-3261 | F10: Speck Presidio2 + MS iPhone 17 Pro Max Deep Sea/Silver Metallic/Spell Blue | G10: =CONCATENATE(E10,"-",B10) -> 151025-3261-151108-3261 | H10: =C10 -> Speck Presidio2 Grip + MagSafe/CC Deep Sea iPhone 18 Pro Max
A11: Speck | B11: 151108-D143 | C11: Speck Presidio2 Grip + MagSafe/CC Black iPhone 18 Pro Max | D11: iPhone 18 Pro Max | E11: 150986-D143 | F11: Speck Presidio2 Grip iPhone 17 Pro Max Black | G11: =CONCATENATE(E11,"-",B11) -> 150986-D143-151108-D143 | H11: =C11 -> Speck Presidio2 Grip + MagSafe/CC Black iPhone 18 Pro Max
A12: Speck | B12: 151110-3240 | C12: Speck Presidio Perfect Clear + C-MagSafe/CC Clear iPhone 18 Pro Max | D12: iPhone 18 Pro Max | E12: 150981-3240 | F12: Speck Presidio Perfect-Clear iPhone 17 Pro Max Clear | G12: =CONCATENATE(E12,"-",B12) -> 150981-3240-151110-3240 | H12: =C12 -> Speck Presidio Perfect Clear + C-MagSafe/CC Clear iPhone 18 Pro Max
A13: Speck | B13: 151118-9221 | C13: Speck Presidio Lux + C-MagSafe/CC Gold Glitter iPhone 18 Pro Max | D13: iPhone 18 Pro Max | E13: 150987-9221 | F13: Speck Presidio Lux iPhone 17 Pro Max Glitter/Gold | G13: =CONCATENATE(E13,"-",B13) -> 150987-9221-151118-9221 | H13: =C13 -> Speck Presidio Lux + C-MagSafe/CC Gold Glitter iPhone 18 Pro Max
... A18: Uniq | B18: UNIQ-IP6.3P(2026)-KEVAMCBLK | C18: UNIQ HYBRID IPHONE 18 PRO (2026) 6.3 MAGCLICK CHARGING KEVA - CARBON BLACK | D18: iPhone 18 Pro | E18: UNIQ-IP6.3P(2025)-KEVAMCBLK | F18: UNIQ HYBRID IPHONE 17 PRO MAGCLICK CHARGING KEVA - CARBON BLACK (CARBON BLACK) | G18: =CONCATENATE(E18,"-",B18) -> UNIQ-IP6.3P(2025)-KEVAMCBLK-UNIQ-IP6.3P(2026)-KEVAMCBLK | H18: =C18 -> UNIQ HYBRID IPHONE 18 PRO (2026) 6.3 MAGCLICK CHARGING KEVA - CARBON BLACK
A19: Uniq | B19: UNIQ-IP6.9P(2026)-KEVAMCBLK | C19: UNIQ HYBRID IPHONE 18 PRO MAX (2026) 6.9 MAGCLICK CHARGING KEVA - CARBON BLACK | D19: iPhone 18 Pro Max | E19: UNIQ-IP6.9P(2025)-KEVAMCBLK | F19: UNIQ HYBRID IPHONE 17 PRO MAX MAGCLICK CHARGING KEVA - CARBON BLACK (CARBON BLACK) | G19: iPhone 17 Pro Max

Sheet POs
D5: =SUBTOTAL(9,D7:D186) -> 0 | E5: =SUBTOTAL(9,E7:E186) -> 0 | F5: =SUBTOTAL(9,F7:F186) -> 0 | G5: =SUBTOTAL(9,G7:G186) -> 0 | H5: =SUBTOTAL(9,H7:H186) -> 0 | I5: =SUBTOTAL(9,I7:I186) -> 0
A6: Marca | B6: ITEM | C6: Descripción
A7: Nomad | B7: NM00736685 | C7: Nomad Sport Band - 45mm | Ultra Orange
B8: NM009162858 | C8: Nomad Modern Leather Case - iPhone 18 Pro Max | Brown | Nomad Leather
B9: NM009179858 | C9: Nomad Modern Leather Case - iPhone 18 Pro Max | Black | Nomad Leather
B10: NM009247858 | C10: Nomad Modern Leather Case - iPhone 18 Pro | Brown | Nomad Leather
B11: NM009254858 | C11: Nomad Modern Leather Case - iPhone 18 Pro | Black | Nomad Leather
B12: NM011116858 | C12: Nomad Stratos Band - 49mm | Black Titanium | Ultra Orange FKM
B13: NM011123858 | C13: Nomad Stratos Band - 49mm | Natural Titanium | Ultra Orange FKM
B14: NM011284858 | C14: Nomad Modern Leather Case - Airpods Pro 3 | Rustic Brown | Horween
B15: NM011291858 | C15: Nomad Modern Leather Case - Airpods Pro 3 | Black | Horween
B16: NM011697858 | C16: Nomad Rocky Point Band - 46mm/49mm | Carbon Black | Black Hardware
B17: NM01187585 | C17: Nomad AC Adapter - 65W | Slim | Carbide
B18: NM014278858 | C18: Nomad Modern Leather Case - iPhone 17 Pro Max | Brown | Nomad Leather
B19: NM014285858 | C19: Nomad Modern Leather Case - iPhone 17 Pro Max | Black | Nomad Leather
... B30: NM009797858 | C30: Nomad Tempo Band - 46mm | Seagrass
A31: Quikcell | B31: GQC2232 | C31: Quikcell Tempered Glass Screen Protector for iPhone 17 / Pro
B32: QC-LIQUIDG | C32: Quikcell Ultra LIQUID GLASS Screen Protector
B33: QCC3FT-BLK | C33: Quikcell USB-C to USB-C cable 3 ft. 3A current; PVC+Nylon
B34: QCC6FT-BLK | C34: Quikcell CHARGE & SYNC CABLE USB-C to USB-C - 6 ft - Black
B35: QCPD25W-WT | C35: Quikcell PD 25W Single USB-C Port Wall Charger White
B36: QCPD35W-WT | C36: Quikcell 35W PD A+C Dual Ports Wall Charger White
B37: QCVPA2005 | C37: Quikcell 37W DUAL PORT A+C CAR CHARGER - Black
A38: Speck | B38: 127573-9166 | C38: Speck Transfer Pro Pocket Universal Sleeve 13"/14" - Sweater Grey/Coastal Blue
B39: 140548-1050 | C39: Speck Balance Folio Case with Microban for iPad Pro 11" M1/Air 10.9" - Black
B40: 140999-1050 | C40: Speck Presidio Pro Folio Case for iPad Pro 11" 2/M1/M2 /Air 10.9" 4/5 - Black
B41: 142573-1050 | C41: Speck Balance Folio with Microban for iPad mini 6 - Black
B42: 144896-9352 | C42: Speck Smartshell Case with Microban for Macbook Pro 14" M1/M2 - Swell Blue
B43: 150225-3085 | C43: Speck Smartshell Case for Macbook Air 13" M2 2022 - Obsidian
B44: 150225-3086 | C44: Speck Smartshell Macbook Air M2/M3 Cozy Pink/Cozy Pink/Swtrgrey
B45: 150225-9992 | C45: Speck Smartshell Macbook Air M2/M3 Clear/Clear/Sweatergrey
B46: 150226-7265 | C46: Speck Balance Folio Case for iPad 10th Gen - Plumberry/Crushed Purple/Crepe Pink
B47: 150226-9969 | C47: Speck Balance Folio Case for iPad 10th Gen - Almond Milk /Mocha/Charcoal
B48: 150226-D143 | C48: Speck Balance Folio Case for iPad 10th Gen - Black/Black/White
B49: 150422-1041 | C49: Speck Car Vent Mount for MagSafe Black iPhone 15 Car
B50: 150423-1041 | C50: Speck Wallet for MagSafe® Black iPhone 15 Wallet
... B103: 151119-5085 | C103: Speck Presidio Perfect Clear Fold + MagSafe Clear iPhone 18 FOLD
A104: Tech21 | B104: T21-10260 | C104: Tech21 EvoLite for iPhone 15 - Clear
B105: T21-10441 | C105: Tech21 EvoLite for iPhone 15 - Lavender
B106: T21-10857 | C106: Tech21 EvoCrystal w/MagSafe for iPhone 16 - Black
...

Sheet Detalle
G1: =SUBTOTAL(9,G3:G181) -> 18720 | H1: =SUBTOTAL(9,H3:H181) -> 3980 | I1: =SUBTOTAL(9,I3:I181) -> 8385 | J1: =SUBTOTAL(9,J3:J181) -> 15716 | K1: =SUBTOTAL(9,K3:K181) -> 13785 | L1: =SUBTOTAL(9,L3:L181) -> 18532 | M1: =SUBTOTAL(9,M3:M181) -> 17672 | N1: =SUBTOTAL(9,N3:N181) -> 158466 | ... U1: =SUBTOTAL(9,U3:U181) -> 0 | AJ1: =SUBTOTAL(9,AJ3:AJ181) -> 1309 | AK1: =SUBTOTAL(9,AK3:AK181) -> 2277 | AL1: =SUBTOTAL(9,AL3:AL181) -> 3426 | AM1: =SUBTOTAL(9,AM3:AM181) -> 8571 | AN1: =SUBTOTAL(9,AN3:AN181) -> 16309 | AO1: =SUBTOTAL(9,AO3:AO181) -> 14566 | AS1: =SUBTOTAL(9,AS3:AS172) -> 594 | AT1: =SUBTOTAL(9,AT3:AT172) -> 1483 | AU1: =SUBTOTAL(9,AU3:AU172) -> 3125 | AV1: =SUBTOTAL(9,AV3:AV172) -> 8229 | AW1: =SUBTOTAL(9,AW3:AW172) -> 15941 | AX1: =SUBTOTAL(9,AX3:AX172) -> 14225 | BA1: =SUBTOTAL(9,BA3:BA181) -> 6936712.6 | BB1: =SUBTOTAL(9,BB3:BB181) -> 9461611.6 | BC1: =SUBTOTAL(9,BC3:BC181) -> 13460447 | BD1: =SUBTOTAL(9,BD3:BD181) -> 13387341 | BE1: =SUBTOTAL(9,BE3:BE181) -> 16356581 | BF1: =SUBTOTAL(9,BF3:BF181) -> 14956958
A2: Marca | B2: ITEM | C2: Descripción | D2: Clase | E2: Estatus | F2: Cost USD | G2: Roll Out | H2: Suma de Nec Jul | I2: Suma de Nec Aug | J2: Suma de Nec Sep | K2: Suma de Nec Oct | L2: Suma de Nec Nov | M2: Suma de Nec Dec | N2: OH ACA | O2: OO Jun | P2: OO Jul | Q2: OO Aug | R2: OO Sep | S2: OO Oct | T2: OO Nov | U2: OO Dec | V2: INV Final JUL | W2: INV Final AUG | X2: INV Final SEP | Y2: INV Final OCT | Z2: INV Final NOV | AA2: INV Final DEC | AB2: Esquema | AC2: Par iP17 | AD2: INV Aj Jul | AE2: INV Aj Aug | AF2: INV Aj Sep | AG2: INV Aj Oct | AH2: INV Aj Nov | AI2: INV Aj Dec | AJ2: In WHS Jul | AK2: In WHS Aug | AL2: In WHS Sep | AM2: In WHS Oct | AN2: In WHS Nov | AO2: In WHS Dec | AP2: W25 - Comentarios Generales | AQ2: x | AR2: Safety Stock | AS2: Safety PO Jul | AT2: Safety PO Aug | AU2: Safety PO Sep | AV2: Safety PO Oct | AW2: Safety PO Nov | AX2: Safety PO Dec | AY2: W27 - Comentarios Generales | AZ2: W30 comentarios Generales | BA2: Jul | BB2: Aug | BC2: Sep | BD2: Oct | BE2: Nov | BF2: Dec
A3: Speck | B3: 127573-9166 | C3: Speck Transfer Pro Pocket Universal Sleeve 13"/14" - Sweater Grey/Coastal Blue | D3: 13" Sleeves | E3: Activo | F3: 11 | G3: 0 | H3: =SUMIF(Consenso!$C:$C,$B3,Consenso!AM:AM) -> 9 | I3: =SUMIF(Consenso!$C:$C,$B3,Consenso!AN:AN) -> 21 | J3: =SUMIF(Consenso!$C:$C,$B3,Consenso!AO:AO) -> 12 | K3: =SUMIF(Consenso!$C:$C,$B3,Consenso!AP:AP) -> 33 | L3: =SUMIF(Consenso!$C:$C,$B3,Consenso!AQ:AQ) -> 12 | M3: =SUMIF(Consenso!$C:$C,$B3,Consenso!AR:AR) -> 12 | N3: =IFERROR(VLOOKUP(B:B,Consenso!C:P,14,0),0) -> 0 | O3: =SUMIF('On Orders'!$B:$B,$B3,'On Orders'!E:E) -> 0 | P3: =SUMIF('On Orders'!$B:$B,$B3,'On Orders'!F:F) -> 48 | Q3: =SUMIF('On Orders'!$B:$B,$B3,'On Orders'!G:G) -> 0 | R3: =SUMIF('On Orders'!$B:$B,$B3,'On Orders'!H:H) -> 0 | S3: 0 | T3: 0 | U3: 0 | V3: =(N3+O3+P3)-H3 -> 39 | W3: =(V3+Q3)-I3 -> 18 | X3: =(W3+R3)-J3 -> 6 | Y3: =(X3+S3)-K3 -> -27 | Z3: =(Y3+T3)-L3 -> -39 | AA3: =(Z3+U3)-M3 -> -51 | AB3: =IF(COUNTIF('Master iP17 iP18'!$B:$B,$B3)>0,"18",IF(COUNTIF('Master iP17 iP18'!$E:$E,$B3)>0,"17","NORMAL")) -> NORMAL | AC3: =IF($AB3="18",_xlfn.XLOOKUP($B3,'Master iP17 iP18'!$B:$B,'Master iP17 iP18'!$E:$E),"") | AD3: =IF($AB3="18",V3+IFERROR(_xlfn.XLOOKUP($AC3,$B:$B,V:V),0),V3) -> 39 | AE3: =IF($AB3="18",W3+IFERROR(_xlfn.XLOOKUP($AC3,$B:$B,W:W),0),W3) -> 18 | AF3: =IF($AB3="18",X3+IFERROR(_xlfn.XLOOKUP($AC3,$B:$B,X:X),0),X3) -> 6 | AG3: =IF($AB3="18",Y3+IFERROR(_xlfn.XLOOKUP($AC3,$B:$B,Y:Y),0),Y3) -> -27 | AH3: =IF($AB3="18",Z3+IFERROR(_xlfn.XLOOKUP($AC3,$B:$B,Z:Z),0),Z3) -> -39 | AI3: =IF($AB3="18",AA3+IFERROR(_xlfn.XLOOKUP($AC3,$B:$B,AA:AA),0),AA3) -> -51 | AJ3: =IF($AB3="17",0,MAX(0,-AD3)) -> 0 | AK3: =IF($AB3="17",0,MAX(0,MAX(0,-AE3)-MAX(0,-AD3))) -> 0 | AL3: =IF($AB3="17",0,MAX(0,MAX(0,-AF3)-MAX(0,-AE3))) -> 0 | AM3: =IF($AB3="17",0,MAX(0,MAX(0,-AG3)-MAX(0,-AF3))) -> 27 | AN3: =IF($AB3="17",0,MAX(0,MAX(0,-AH3)-MAX(0,-AG3))) -> 12 | AO3: =IF($AB3="17",0,MAX(0,MAX(0,-AI3)-MAX(0,-AH3))) -> 12 | AP3: Poner PO 40 Mediados Julio | AR3: =IFERROR(_xlfn.XLOOKUP(B3,#REF!,#REF!),"") | AS3: =IF($AR3="A",AJ3*1.2,IF($AR3="B",AJ3*1.1,AJ3)) -> 0 | AT3: =IF($AR3="A",AK3*1.2,IF($AR3="B",AK3*1.1,AK3)) -> 0 | AU3: =IF($AR3="A",AL3*1.2,IF($AR3="B",AL3*1.1,AL3)) -> 0 | AV3: =IF($AR3="A",AM3*1.2,IF($AR3="B",AM3*1.1,AM3)) -> 27 | AW3: =IF($AR3="A",AN3*1.2,IF($AR3="B",AN3*1.1,AN3)) -> 12 | AX3: =IF($AR3="A",AO3*1.2,IF($AR3="B",AO3*1.1,AO3)) -> 12 | BA3: =SUMIF(Consenso!$C:$C,$B3,Consenso!AZ:AZ) -> 5386.83 | BB3: =SUMIF(Consenso!$C:$C,$B3,Consenso!BA:BA) -> 19118.8 | BC3: =SUMIF(Consenso!$C:$C,$B3,Consenso!BB:BB) -> 11212.92 | BD3: =SUMIF(Consenso!$C:$C,$B3,Consenso!BC:BC) -> 19751.71 | BE3: =SUMIF(Consenso!$C:$C,$B3,Consenso!BD:BD) -> 11716.73 | BF3: =SUMIF(Consenso!$C:$C,$B3,Consenso!BE:BE) -> 14235.78
A4: Speck | B4: 150226-7265 | C4: Speck Balance Folio Case for iPad 10th Gen - Plumberry/Crushed Purple/Crepe Pink | D4: iPad 10th /11th - 10.9"/11" (2022-2025) | E4: Activo | F4: 14 | G4: 0 | H4: =SUMIF(Consenso!$C:$C,$B4,Consenso!AM:AM) -> 0 | I4: =SUMIF(Consenso!$C:$C,$B4,Consenso!AN:AN) -> 268 | J4: =SUMIF(Consenso!$C:$C,$B4,Consenso!AO:AO) -> 120 | K4: =SUMIF(Consenso!$C:$C,$B4,Consenso!AP:AP) -> 90 | L4: =SUMIF(Consenso!$C:$C,$B4,Consenso!AQ:AQ) -> 320 | M4: =SUMIF(Consenso!$C:$C,$B4,Consenso!AR:AR) -> 110 | N4: =IFERROR(VLOOKUP(B:B,Consenso!C:P,14,0),0) -> 0 | O4: =SUMIF('On Orders'!$B:$B,$B4,'On Orders'!E:E) -> 0 | P4: =SUMIF('On Orders'!$B:$B,$B4,'On Orders'!F:F) -> 352 | Q4: =SUMIF('On Orders'!$B:$B,$B4,'On Orders'!G:G) -> 0 | R4: =SUMIF('On Orders'!$B:$B,$B4,'On Orders'!H:H) -> 0 | S4: 0 | T4: 0 | U4: 0 | V4: =(N4+O4+P4)-H4 -> 352 | W4: =(V4+Q4)-I4 -> 84 | X4: =(W4+R4)-J4 -> -36 | Y4: =(X4+S4)-K4 -> -126 | Z4: =(Y4+T4)-L4 -> -446 | AA4: =(Z4+U4)-M4 -> -556 | AB4: =IF(COUNTIF('Master iP17 iP18'!$B:$B,$B4)>0,"18",IF(COUNTIF('Master iP17 iP18'!$E:$E,$B4)>0,"17","NORMAL")) -> NORMAL | AC4: =IF($AB4="18",_xlfn.XLOOKUP($B4,'Master iP17 iP18'!$B:$B,'Master iP17 iP18'!$E:$E),"") | AD4: =IF($AB4="18",V4+IFERROR(_xlfn.XLOOKUP($AC4,$B:$B,V:V),0),V4) -> 352 | AE4: =IF($AB4="18",W4+IFERROR(_xlfn.XLOOKUP($AC4,$B:$B,W:W),0),W4) -> 84 | AF4: =IF($AB4="18",X4+IFERROR(_xlfn.XLOOKUP($AC4,$B:$B,X:X),0),X4) -> -36 | AG4: =IF($AB4="18",Y4+IFERROR(_xlfn.XLOOKUP($AC4,$B:$B,Y:Y),0),Y4) -> -126 | AH4: =IF($AB4="18",Z4+IFERROR(_xlfn.XLOOKUP($AC4,$B:$B,Z:Z),0),Z4) -> -446 | AI4: =IF($AB4="18",AA4+IFERROR(_xlfn.XLOOKUP($AC4,$B:$B,AA:AA),0),AA4) -> -556 | AJ4: =IF($AB4="17",0,MAX(0,-AD4)) -> 0 | AK4: =IF($AB4="17",0,MAX(0,MAX(0,-AE4)-MAX(0,-AD4))) -> 0 | AL4: =IF($AB4="17",0,MAX(0,MAX(0,-AF4)-MAX(0,-AE4))) -> 36 | AM4: =IF($AB4="17",0,MAX(0,MAX(0,-AG4)-MAX(0,-AF4))) -> 90 | AN4: =IF($AB4="17",0,MAX(0,MAX(0,-AH4)-MAX(0,-AG4))) -> 320 | AO4: =IF($AB4="17",0,MAX(0,MAX(0,-AI4)-MAX(0,-AH4))) -> 110 | AP4: PO 350 Med Julio | AR4: =IFERROR(_xlfn.XLOOKUP(B4,#REF!,#REF!),"") | AS4: =IF($AR4="A",AJ4*1.2,IF($AR4="B",AJ4*1.1,AJ4)) -> 0 | AT4: =IF($AR4="A",AK4*1.2,IF($AR4="B",AK4*1.1,AK4)) -> 0 | AU4: =IF($AR4="A",AL4*1.2,IF($AR4="B",AL4*1.1,AL4)) -> 36 | AV4: =IF($AR4="A",AM4*1.2,IF($AR4="B",AM4*1.1,AM4)) -> 90 | AW4: =IF($AR4="A",AN4*1.2,IF($AR4="B",AN4*1.1,AN4)) -> 320 | AX4: =IF($AR4="A",AO4*1.2,IF($AR4="B",AO4*1.1,AO4)) -> 110 | AY4: Volar 352 - PO / FCST 1,400 resto del año | BA4: =SUMIF(Consenso!$C:$C,$B4,Consenso!AZ:AZ) -> 20656.21 | BB4: =SUMIF(Consenso!$C:$C,$B4,Consenso!BA:BA) -> 156209.41 | BC4: =SUMIF(Consenso!$C:$C,$B4,Consenso!BB:BB) -> 77366.31 | BD4: =SUMIF(Consenso!$C:$C,$B4,Consenso!BC:BC) -> 71501.65 | BE4: =SUMIF(Consenso!$C:$C,$B4,Consenso!BD:BD) -> 176585.37 | BF4: =SUMIF(Consenso!$C:$C,$B4,Consenso!BE:BE) -> 90189.85
A5: Speck | B5: 150226-9969 | C5: Speck Balance Folio Case for iPad 10th Gen - Almond Milk /Mocha/Charcoal | D5: iPad 10th /11th - 10.9"/11" (2022-2025) | E5: Activo | F5: 14 | G5: 0 | H5: =SUMIF(Consenso!$C:$C,$B5,Consenso!AM:AM) -> 73 | I5: =SUMIF(Consenso!$C:$C,$B5,Consenso!AN:AN) -> 175 | J5: =SUMIF(Consenso!$C:$C,$B5,Consenso!AO:AO) -> 123 | K5: =SUMIF(Consenso!$C:$C,$B5,Consenso!AP:AP) -> 80 | L5: =SUMIF(Consenso!$C:$C,$B5,Consenso!AQ:AQ) -> 280 | M5: =SUMIF(Consenso!$C:$C,$B5,Consenso!AR:AR) -> 95 | N5: =IFERROR(VLOOKUP(B:B,Consenso!C:P,14,0),0) -> 38 | O5: =SUMIF('On Orders'!$B:$B,$B5,'On Orders'!E:E) -> 0 | P5: =SUMIF('On Orders'!$B:$B,$B5,'On Orders'!F:F) -> 160 | Q5: =SUMIF('On Orders'!$B:$B,$B5,'On Orders'!G:G) -> 0 | R5: =SUMIF('On Orders'!$B:$B,$B5,'On Orders'!H:H) -> 0 | S5: 0 | T5: 0 | U5: 0 | V5: =(N5+O5+P5)-H5 -> 125 | W5: =(V5+Q5)-I5 -> -50 | X5: =(W5+R5)-J5 -> -173 | Y5: =(X5+S5)-K5 -> -253 | Z5: =(Y5+T5)-L5 -> -533 | AA5: =(Z5+U5)-M5 -> -628 | AB5: =IF(COUNTIF('Master iP17 iP18'!$B:$B,$B5)>0,"18",IF(COUNTIF('Master iP17 iP18'!$E:$E,$B5)>0,"17","NORMAL")) -> NORMAL | AC5: =IF($AB5="18",_xlfn.XLOOKUP($B5,'Master iP17 iP18'!$B:$B,'Master iP17 iP18'!$E:$E),"") | AD5: =IF($AB5="18",V5+IFERROR(_xlfn.XLOOKUP($AC5,$B:$B,V:V),0),V5) -> 125 | AE5: =IF($AB5="18",W5+IFERROR(_xlfn.XLOOKUP($AC5,$B:$B,W:W),0),W5) -> -50 | AF5: =IF($AB5="18",X5+IFERROR(_xlfn.XLOOKUP($AC5,$B:$B,X:X),0),X5) -> -173 | AG5: =IF($AB5="18",Y5+IFERROR(_xlfn.XLOOKUP($AC5,$B:$B,Y:Y),0),Y5) -> -253 | AH5: =IF($AB5="18",Z5+IFERROR(_xlfn.XLOOKUP($AC5,$B:$B,Z:Z),0),Z5) -> -533 | AI5: =IF($AB5="18",AA5+IFERROR(_xlfn.XLOOKUP($AC5,$B:$B,AA:AA),0),AA5) -> -628 | AJ5: =IF($AB5="17",0,MAX(0,-AD5)) -> 0 | AK5: =IF($AB5="17",0,MAX(0,MAX(0,-AE5)-MAX(0,-AD5))) -> 50 | AL5: =IF($AB5="17",0,MAX(0,MAX(0,-AF5)-MAX(0,-AE5))) -> 123 | AM5: =IF($AB5="17",0,MAX(0,MAX(0,-AG5)-MAX(0,-AF5))) -> 80 | AN5: =IF($AB5="17",0,MAX(0,MAX(0,-AH5)-MAX(0,-AG5))) -> 280 | AO5: =IF($AB5="17",0,MAX(0,MAX(0,-AI5)-MAX(0,-AH5))) -> 95 | AP5: PO 130 Med Julio | AR5: =IFERROR(_xlfn.XLOOKUP(B5,#REF!,#REF!),"") | AS5: =IF($AR5="A",AJ5*1.2,IF($AR5="B",AJ5*1.1,AJ5)) -> 0 | AT5: =IF($AR5="A",AK5*1.2,IF($AR5="B",AK5*1.1,AK5)) -> 50 | AU5: =IF($AR5="A",AL5*1.2,IF($AR5="B",AL5*1.1,AL5)) -> 123 | AV5: =IF($AR5="A",AM5*1.2,IF($AR5="B",AM5*1.1,AM5)) -> 80 | AW5: =IF($AR5="A",AN5*1.2,IF($AR5="B",AN5*1.1,AN5)) -> 280 | AX5: =IF($AR5="A",AO5*1.2,IF($AR5="B",AO5*1.1,AO5)) -> 95 | AY5: PO / FCST 650 resto del año | AZ5: PO 170 | BA5: =SUMIF(Consenso!$C:$C,$B5,Consenso!AZ:AZ) -> 52090.01 | BB5: =SUMIF(Consenso!$C:$C,$B5,Consenso!BA:BA) -> 109614.08 | BC5: =SUMIF(Consenso!$C:$C,$B5,Consenso!BB:BB) -> 81680.97 | BD5: =SUMIF(Consenso!$C:$C,$B5,Consenso!BC:BC) -> 64676.6 | BE5: =SUMIF(Consenso!$C:$C,$B5,Consenso!BD:BD) -> 156842.32 | BF5: =SUMIF(Consenso!$C:$C,$B5,Consenso!BE:BE) -> 69942.99
A6: Speck | B6: 150226-D143 | C6: Speck Balance Folio Case for iPad 10th Gen - Black/Black/White | D6: iPad 10th /11th - 10.9"/11" (2022-2025) | E6: Activo | F6: 14 | G6: 0 | H6: =SUMIF(Consenso!$C:$C,$B6,Consenso!AM:AM) -> 49 | I6: =SUMIF(Consenso!$C:$C,$B6,Consenso!AN:AN) -> 244 | J6: =SUMIF(Consenso!$C:$C,$B6,Consenso!AO:AO) -> 134 | K6: =SUMIF(Consenso!$C:$C,$B6,Consenso!AP:AP) -> 80 | L6: =SUMIF(Consenso!$C:$C,$B6,Consenso!AQ:AQ) -> 300 | M6: =SUMIF(Consenso!$C:$C,$B6,Consenso!AR:AR) -> 70 | N6: =IFERROR(VLOOKUP(B:B,Consenso!C:P,14,0),0) -> 91 | O6: =SUMIF('On Orders'!$B:$B,$B6,'On Orders'!E:E) -> 0 | P6: =SUMIF('On Orders'!$B:$B,$B6,'On Orders'!F:F) -> 192 | Q6: =SUMIF('On Orders'!$B:$B,$B6,'On Orders'!G:G) -> 0 | R6: =SUMIF('On Orders'!$B:$B,$B6,'On Orders'!H:H) -> 0 | S6: 0 | T6: 0 | U6: 0 | V6: =(N6+O6+P6)-H6 -> 234 | W6: =(V6+Q6)-I6 -> -10 | X6: =(W6+R6)-J6 -> -144 | Y6: =(X6+S6)-K6 -> -224 | Z6: =(Y6+T6)-L6 -> -524 | AA6: =(Z6+U6)-M6 -> -594 | AB6: =IF(COUNTIF('Master iP17 iP18'!$B:$B,$B6)>0,"18",IF(COUNTIF('Master iP17 iP18'!$E:$E,$B6)>0,"17","NORMAL")) -> NORMAL | AC6: =IF($AB6="18",_xlfn.XLOOKUP($B6,'Master iP17 iP18'!$B:$B,'Master iP17 iP18'!$E:$E),"") | AD6: =IF($AB6="18",V6+IFERROR(_xlfn.XLOOKUP($AC6,$B:$B,V:V),0),V6) -> 234 | AE6: =IF($AB6="18",W6+IFERROR(_xlfn.XLOOKUP($AC6,$B:$B,W:W),0),W6) -> -10 | AF6: =IF($AB6="18",X6+IFERROR(_xlfn.XLOOKUP($AC6,$B:$B,X:X),0),X6) -> -144 | AG6: =IF($AB6="18",Y6+IFERROR(_xlfn.XLOOKUP($AC6,$B:$B,Y:Y),0),Y6) -> -224 | AH6: =IF($AB6="18",Z6+IFERROR(_xlfn.XLOOKUP($AC6,$B:$B,Z:Z),0),Z6) -> -524 | AI6: =IF($AB6="18",AA6+IFERROR(_xlfn.XLOOKUP($AC6,$B:$B,AA:AA),0),AA6) -> -594 | AJ6: =IF($AB6="17",0,MAX(0,-AD6)) -> 0 | AK6: =IF($AB6="17",0,MAX(0,MAX(0,-AE6)-MAX(0,-AD6))) -> 10 | AL6: =IF($AB6="17",0,MAX(0,MAX(0,-AF6)-MAX(0,-AE6))) -> 134 | AM6: =IF($AB6="17",0,MAX(0,MAX(0,-AG6)-MAX(0,-AF6))) -> 80 | AN6: =IF($AB6="17",0,MAX(0,MAX(0,-AH6)-MAX(0,-AG6))) -> 300 | AO6: =IF($AB6="17",0,MAX(0,MAX(0,-AI6)-MAX(0,-AH6))) -> 70 | AP6: PO 180 Med Julio | AR6: =IFERROR(_xlfn.XLOOKUP(B6,#REF!,#REF!),"") | AS6: =IF($AR6="A",AJ6*1.2,IF($AR6="B",AJ6*1.1,AJ6)) -> 0 | AT6: =IF($AR6="A",AK6*1.2,IF($AR6="B",AK6*1.1,AK6)) -> 10 | AU6: =IF($AR6="A",AL6*1.2,IF($AR6="B",AL6*1.1,AL6)) -> 134 | AV6: =IF($AR6="A",AM6*1.2,IF($AR6="B",AM6*1.1,AM6)) -> 80 | AW6: =IF($AR6="A",AN6*1.2,IF($AR6="B",AN6*1.1,AN6)) -> 300 | AX6: =IF($AR6="A",AO6*1.2,IF($AR6="B",AO6*1.1,AO6)) -> 70 | AY6: PO / FCST 650 resto del año | AZ6: PO 150 | BA6: =SUMIF(Consenso!$C:$C,$B6,Consenso!AZ:AZ) -> 23211.79 | BB6: =SUMIF(Consenso!$C:$C,$B6,Consenso!BA:BA) -> 115585.24 | BC6: =SUMIF(Consenso!$C:$C,$B6,Consenso!BB:BB) -> 63477.14 | BD6: =SUMIF(Consenso!$C:$C,$B6,Consenso!BC:BC) -> 37896.8 | BE6: =SUMIF(Consenso!$C:$C,$B6,Consenso!BD:BD) -> 142113 | BF6: =SUMIF(Consenso!$C:$C,$B6,Consenso!BE:BE) -> 33159.7
A7: Speck | B7: 144896-9352 | C7: Speck Smartshell Case with Microban for Macbook Pro 14" M1/M2 - Swell Blue | D7: MacBook Pro 14" M1/M2 Cases | E7: Activo | F7: 14 | G7: 0 | H7: =SUMIF(Consenso!$C:$C,$B7,Consenso!AM:AM) -> 28 | I7: =SUMIF(Consenso!$C:$C,$B7,Consenso!AN:AN) -> 60 | J7: =SUMIF(Consenso!$C:$C,$B7,Consenso!AO:AO) -> 30 | K7: =SUMIF(Consenso!$C:$C,$B7,Consenso!AP:AP) -> 30 | L7: =SUMIF(Consenso!$C:$C,$B7,Consenso!AQ:AQ) -> 90 | M7: =SUMIF(Consenso!$C:$C,$B7,Consenso!AR:AR) -> 40 | N7: =IFERROR(VLOOKUP(B:B,Consenso!C:P,14,0),0) -> 27 | O7: =SUMIF('On Orders'!$B:$B,$B7,'On Orders'!E:E) -> 0 | P7: =SUMIF('On Orders'!$B:$B,$B7,'On Orders'!F:F) -> 64 | Q7: =SUMIF('On Orders'!$B:$B,$B7,'On Orders'!G:G) -> 0 | R7: =SUMIF('On Orders'!$B:$B,$B7,'On Orders'!H:H) -> 0 | S7: 0 | T7: 0 | U7: 0 | V7: =(N7+O7+P7)-H7 -> 63 | W7: =(V7+Q7)-I7 -> 3 | X7: =(W7+R7)-J7 -> -27 | Y7: =(X7+S7)-K7 -> -57 | Z7: =(Y7+T7)-L7 -> -147 | AA7: =(Z7+U7)-M7 -> -187 | AB7: =IF(COUNTIF('Master iP17 iP18'!$B:$B,$B7)>0,"18",IF(COUNTIF('Master iP17 iP18'!$E:$E,$B7)>0,"17","NORMAL")) -> NORMAL | AC7: =IF($AB7="18",_xlfn.XLOOKUP($B7,'Master iP17 iP18'!$B:$B,'Master iP17 iP18'!$E:$E),"") | AD7: =IF($AB7="18",V7+IFERROR(_xlfn.XLOOKUP($AC7,$B:$B,V:V),0),V7) -> 63 | AE7: =IF($AB7="18",W7+IFERROR(_xlfn.XLOOKUP($AC7,$B:$B,W:W),0),W7) -> 3 | AF7: =IF($AB7="18",X7+IFERROR(_xlfn.XLOOKUP($AC7,$B:$B,X:X),0),X7) -> -27 | AG7: =IF($AB7="18",Y7+IFERROR(_xlfn.XLOOKUP($AC7,$B:$B,Y:Y),0),Y7) -> -57 | AH7: =IF($AB7="18",Z7+IFERROR(_xlfn.XLOOKUP($AC7,$B:$B,Z:Z),0),Z7) -> -147 | AI7: =IF($AB7="18",AA7+IFERROR(_xlfn.XLOOKUP($AC7,$B:$B,AA:AA),0),AA7) -> -187 | AJ7: =IF($AB7="17",0,MAX(0,-AD7)) -> 0 | AK7: =IF($AB7="17",0,MAX(0,MAX(0,-AE7)-MAX(0,-AD7))) -> 0 | AL7: =IF($AB7="17",0,MAX(0,MAX(0,-AF7)-MAX(0,-AE7))) -> 27 | AM7: =IF($AB7="17",0,MAX(0,MAX(0,-AG7)-MAX(0,-AF7))) -> 30 | AN7: =IF($AB7="17",0,MAX(0,MAX(0,-AH7)-MAX(0,-AG7))) -> 90 | AO7: =IF($AB7="17",0,MAX(0,MAX(0,-AI7)-MAX(0,-AH7))) -> 40 | AP7: PO 50 Med Julio | AR7: =IFERROR(_xlfn.XLOOKUP(B7,#REF!,#REF!),"") | AS7: =IF($AR7="A",AJ7*1.2,IF($AR7="B",AJ7*1.1,AJ7)) -> 0 | AT7: =IF($AR7="A",AK7*1.2,IF($AR7="B",AK7*1.1,AK7)) -> 0 | AU7: =IF($AR7="A",AL7*1.2,IF($AR7="B",AL7*1.1,AL7)) -> 27 | AV7: =IF($AR7="A",AM7*1.2,IF($AR7="B",AM7*1.1,AM7)) -> 30 | AW7: =IF($AR7="A",AN7*1.2,IF($AR7="B",AN7*1.1,AN7)) -> 90 | AX7: =IF($AR7="A",AO7*1.2,IF($AR7="B",AO7*1.1,AO7)) -> 40 | AY7: PO FCST / 200 | BA7: =SUMIF(Consenso!$C:$C,$B7,Consenso!AZ:AZ) -> 12056.8 | BB7: =SUMIF(Consenso!$C:$C,$B7,Consenso!BA:BA) -> 25836 | BC7: =SUMIF(Consenso!$C:$C,$B7,Consenso!BB:BB) -> 12918 | BD7: =SUMIF(Consenso!$C:$C,$B7,Consenso!BC:BC) -> 12918 | BE7: =SUMIF(Consenso!$C:$C,$B7,Consenso!BD:BD) -> 38754 | BF7: =SUMIF(Consenso!$C:$C,$B7,Consenso!BE:BE) -> 17224
A8: Speck | B8: 150225-3085 | C8: Speck Smartshell Case for Macbook Air 13" M2 2022 - Obsidian | D8: MacBook Air 13" M4/M3/M2 | E8: Activo | F8: 14 | G8: 0 | H8: =SUMIF(Consenso!$C:$C,$B8,Consenso!AM:AM) -> 59 | I8: =SUMIF(Consenso!$C:$C,$B8,Consenso!AN:AN) -> 200 | J8: =SUMIF(Consenso!$C:$C,$B8,Consenso!AO:AO) -> 90 | K8: =SUMIF(Consenso!$C:$C,$B8,Consenso!AP:AP) -> 55 | L8: =SUMIF(Consenso!$C:$C,$B8,Consenso!AQ:AQ) -> 200 | M8: =SUMIF(Consenso!$C:$C,$B8,Consenso!AR:AR) -> 90 | N8: =IFERROR(VLOOKUP(B:B,Consenso!C:P,14,0),0) -> 45 | O8: =SUMIF('On Orders'!$B:$B,$B8,'On Orders'!E:E) -> 0 | P8: =SUMIF('On Orders'!$B:$B,$B8,'On Orders'!F:F) -> 240 | Q8: =SUMIF('On Orders'!$B:$B,$B8,'On Orders'!G:G) -> 0 | R8: =SUMIF('On Orders'!$B:$B,$B8,'On Orders'!H:H) -> 0 | S8: 0 | T8: 0 | U8: 0 | V8: =(N8+O8+P8)-H8 -> 226 | W8: =(V8+Q8)-I8 -> 26 | X8: =(W8+R8)-J8 -> -64 | Y8: =(X8+S8)-K8 -> -119 | Z8: =(Y8+T8)-L8 -> -319 | AA8: =(Z8+U8)-M8 -> -409 | AB8: =IF(COUNTIF('Master iP17 iP18'!$B:$B,$B8)>0,"18",IF(COUNTIF('Master iP17 iP18'!$E:$E,$B8)>0,"17","NORMAL")) -> NORMAL | AC8: =IF($AB8="18",_xlfn.XLOOKUP($B8,'Master iP17 iP18'!$B:$B,'Master iP17 iP18'!$E:$E),"") | AD8: =IF($AB8="18",V8+IFERROR(_xlfn.XLOOKUP($AC8,$B:$B,V:V),0),V8) -> 226 | AE8: =IF($AB8="18",W8+IFERROR(_xlfn.XLOOKUP($AC8,$B:$B,W:W),0),W8) -> 26 | AF8: =IF($AB8="18",X8+IFERROR(_xlfn.XLOOKUP($AC8,$B:$B,X:X),0),X8) -> -64 | AG8: =IF($AB8="18",Y8+IFERROR(_xlfn.XLOOKUP($AC8,$B:$B,Y:Y),0),Y8) -> -119 | AH8: =IF($AB8="18",Z8+IFERROR(_xlfn.XLOOKUP($AC8,$B:$B,Z:Z),0),Z8) -> -319 | AI8: =IF($AB8="18",AA8+IFERROR(_xlfn.XLOOKUP($AC8,$B:$B,AA:AA),0),AA8) -> -409 | AJ8: =IF($AB8="17",0,MAX(0,-AD8)) -> 0 | AK8: =IF($AB8="17",0,MAX(0,MAX(0,-AE8)-MAX(0,-AD8))) -> 0 | AL8: =IF($AB8="17",0,MAX(0,MAX(0,-AF8)-MAX(0,-AE8))) -> 64 | AM8: =IF($AB8="17",0,MAX(0,MAX(0,-AG8)-MAX(0,-AF8))) -> 55 | AN8: =IF($AB8="17",0,MAX(0,MAX(0,-AH8)-MAX(0,-AG8))) -> 200 | AO8: =IF($AB8="17",0,MAX(0,MAX(0,-AI8)-MAX(0,-AH8))) -> 90 | AP8: PO 230 Med Julio | AR8: =IFERROR(_xlfn.XLOOKUP(B8,#REF!,#REF!),"") | AS8: =IF($AR8="A",AJ8*1.2,IF($AR8="B",AJ8*1.1,AJ8)) -> 0 | AT8: =IF($AR8="A",AK8*1.2,IF($AR8="B",AK8*1.1,AK8)) -> 0 | AU8: =IF($AR8="A",AL8*1.2,IF($AR8="B",AL8*1.1,AL8)) -> 64 | AV8: =IF($AR8="A",AM8*1.2,IF($AR8="B",AM8*1.1,AM8)) -> 55 | AW8: =IF($AR8="A",AN8*1.2,IF($AR8="B",AN8*1.1,AN8)) -> 200 | AX8: =IF($AR8="A",AO8*1.2,IF($AR8="B",AO8*1.1,AO8)) -> 90 | AY8: PO FCST / 400 | BA8: =SUMIF(Consenso!$C:$C,$B8,Consenso!AZ:AZ) -> 37496.84 | BB8: =SUMIF(Consenso!$C:$C,$B8,Consenso!BA:BA) -> 119371.46 | BC8: =SUMIF(Consenso!$C:$C,$B8,Consenso!BB:BB) -> 68478.79 | BD8: =SUMIF(Consenso!$C:$C,$B8,Consenso!BC:BC) -> 50888.74 | BE8: =SUMIF(Consenso!$C:$C,$B8,Consenso!BD:BD) -> 118867.65 | BF8: =SUMIF(Consenso!$C:$C,$B8,Consenso!BE:BE) -> 74524.51
A9: Speck | B9: 150225-3086 | C9: Speck Smartshell Macbook Air M2/M3 Cozy Pink/Cozy Pink/Swtrgrey | D9: MacBook Air 13" M4/M3/M2 | E9: Activo | F9: 14 | G9: 0 | H9: =SUMIF(Consenso!$C:$C,$B9,Consenso!AM:AM) -> 18 | I9: =SUMIF(Consenso!$C:$C,$B9,Consenso!AN:AN) -> 55 | J9: =SUMIF(Consenso!$C:$C,$B9,Consenso!AO:AO) -> 42 | K9: =SUMIF(Consenso!$C:$C,$B9,Consenso!AP:AP) -> 30 | L9: =SUMIF(Consenso!$C:$C,$B9,Consenso!AQ:AQ) -> 115 | M9: =SUMIF(Consenso!$C:$C,$B9,Consenso!AR:AR) -> 136 | N9: =IFERROR(VLOOKUP(B:B,Consenso!C:P,14,0),0) -> 84 | O9: =SUMIF('On Orders'!$B:$B,$B9,'On Orders'!E:E) -> 0 | P9: =SUMIF('On Orders'!$B:$B,$B9,'On Orders'!F:F) -> 80 | Q9: =SUMIF('On Orders'!$B:$B,$B9,'On Orders'!G:G) -> 0 | R9: =SUMIF('On Orders'!$B:$B,$B9,'On Orders'!H:H) -> 0 | S9: 0 | T9: 0 | U9: 0 | V9: =(N9+O9+P9)-H9 -> 146 | W9: =(V9+Q9)-I9 -> 91 | X9: =(W9+R9)-J9 -> 49 | Y9: =(X9+S9)-K9 -> 19 | Z9: =(Y9+T9)-L9 -> -96 | AA9: =(Z9+U9)-M9 -> -232 | AB9: =IF(COUNTIF('Master iP17 iP18'!$B:$B,$B9)>0,"18",IF(COUNTIF('Master iP17 iP18'!$E:$E,$B9)>0,"17","NORMAL")) -> NORMAL | AC9: =IF($AB9="18",_xlfn.XLOOKUP($B9,'Master iP17 iP18'!$B:$B,'Master iP17 iP18'!$E:$E),"") | AD9: =IF($AB9="18",V9+IFERROR(_xlfn.XLOOKUP($AC9,$B:$B,V:V),0),V9) -> 146 | AE9: =IF($AB9="18",W9+IFERROR(_xlfn.XLOOKUP($AC9,$B:$B,W:W),0),W9) -> 91 | AF9: =IF($AB9="18",X9+IFERROR(_xlfn.XLOOKUP($AC9,$B:$B,X:X),0),X9) -> 49 | AG9: =IF($AB9="18",Y9+IFERROR(_xlfn.XLOOKUP($AC9,$B:$B,Y:Y),0),Y9) -> 19 | AH9: =IF($AB9="18",Z9+IFERROR(_xlfn.XLOOKUP($AC9,$B:$B,Z:Z),0),Z9) -> -96 | AI9: =IF($AB9="18",AA9+IFERROR(_xlfn.XLOOKUP($AC9,$B:$B,AA:AA),0),AA9) -> -232 | AJ9: =IF($AB9="17",0,MAX(0,-AD9)) -> 0 | AK9: =IF($AB9="17",0,MAX(0,MAX(0,-AE9)-MAX(0,-AD9))) -> 0 | AL9: =IF($AB9="17",0,MAX(0,MAX(0,-AF9)-MAX(0,-AE9))) -> 0 | AM9: =IF($AB9="17",0,MAX(0,MAX(0,-AG9)-MAX(0,-AF9))) -> 0 | AN9: =IF($AB9="17",0,MAX(0,MAX(0,-AH9)-MAX(0,-AG9))) -> 96 | AO9: =IF($AB9="17",0,MAX(0,MAX(0,-AI9)-MAX(0,-AH9))) -> 136 | AP9: PO 80 Med Julio | AR9: =IFERROR(_xlfn.XLOOKUP(B9,#REF!,#REF!),"") | AS9: =IF($AR9="A",AJ9*1.2,IF($AR9="B",AJ9*1.1,AJ9)) -> 0 | AT9: =IF($AR9="A",AK9*1.2,IF($AR9="B",AK9*1.1,AK9)) -> 0 | AU9: =IF($AR9="A",AL9*1.2,IF($AR9="B",AL9*1.1,AL9)) -> 0 | AV9: =IF($AR9="A",AM9*1.2,IF($AR9="B",AM9*1.1,AM9)) -> 0 | AW9: =IF($AR9="A",AN9*1.2,IF($AR9="B",AN9*1.1,AN9)) -> 96 | AX9: =IF($AR9="A",AO9*1.2,IF($AR9="B",AO9*1.1,AO9)) -> 136 | AY9: PO FCST / 300 | BA9: =SUMIF(Consenso!$C:$C,$B9,Consenso!AZ:AZ) -> 22789.54 | BB9: =SUMIF(Consenso!$C:$C,$B9,Consenso!BA:BA) -> 73441.27 | BC9: =SUMIF(Consenso!$C:$C,$B9,Consenso!BB:BB) -> 46290.19 | BD9: =SUMIF(Consenso!$C:$C,$B9,Consenso!BC:BC) -> 52928.93 | BE9: =SUMIF(Consenso!$C:$C,$B9,Consenso!BD:BD) -> 73945.08 | BF9: =SUMIF(Consenso!$C:$C,$B9,Consenso!BE:BE) -> 69900.16
